Workbook

Sheet Sheet1

Sheet 2021-09
A1: 廠商名稱 | B1: 合作模式 | C1: 負責人 | D1: 貨款加總 | E1: 應收總和
A2: 亞仕生醫科技有限公司 | B2: 新約寄倉 | C2: 林京苓 | D2: 292.5 | E2: 199.935
A3: 明奇食品有限公司 | B3: 新約寄倉 | C3: 周芃葳 | D3: 34080 | E3: 26844.52
A4: 萬灃興貿易有限公司 | B4: 新約寄倉 | C4: 白乙君 | D4: 61505.68 | E4: 50332.17
A5: 凱勝運動訓練有限公司 | B5: 新約寄倉 | C5: 白乙君 | D5: 660.68 | E5: -49.882688
A6: 三福生技股份有限公司 | B6: 新約寄倉 | C6: 白乙君 | D6: 1536.8 | E6: 1263.9915
A7: 愛上大數據股份有限公司 | B7: 轉單 | C7: 張所靜 | D7: 7110 | E7: 4550.4
A8: 華格食品國際股份有限公司 | B8: 新約寄倉 | C8: 白乙君 | D8: 238.4 | E8: 177.71
A9: 大誠益國際實業有限公司 | B9: 新約寄倉 | C9: 張所靜 | D9: 13162.38 | E9: 11020.52
A10: 錸臻賦食品行 | B10: 轉單 | C10: 白乙君 | D10: 10183 | E10: 7128.1
A11: 友信農產品行 | B11: 轉單 | C11: 白乙君 | D11: 880 | E11: 616
A12: 登薾國際貿易股份有限公司 | B12: 新約寄倉 | C12: 張所靜 | D12: 1192 | E12: 567.32461
A13: 薌園生技股份有限公司 | B13: 新約寄倉 | C13: 白乙君 | D13: 920 | E13: 556.56973
... A281: 高紘國際股份有限公司 | B281: 新約寄倉 | C281: 謝順平 | D281: 0 | E281: -24.15

Sheet 2021-10
A1: 廠商名稱 | B1: 合作模式 | C1: 負責人 | D1: 貨款加總 | E1: 應收總和
A2: 乙彤食藝有限公司 | B2: 新約寄倉 | C2: 張所靜 | D2: 337.84 | E2: 271.765
A3: 明奇食品有限公司 | B3: 新約寄倉 | C3: 周芃葳 | D3: 47769.6 | E3: 37205.045
A4: 天時生技有限公司 | B4: 轉單 | C4: 白乙君 | D4: 3895 | E4: 2804.4
A5: 派斯克國際有限公司 | B5: 轉單 | C5: 謝順平 | D5: 1999 | E5: 1464.3
A6: 凱勝運動訓練有限公司 | B6: 新約寄倉 | C6: 白乙君 | D6: 1910.4 | E6: 903.05679
A7: 泰鴻食品股份有限公司 | B7: 轉單 | C7: 張所靜 | D7: 4982 | E7: 3487.4
A8: 裕盛昇有限公司 | B8: 轉單 | C8: 張所靜 | D8: 689 | E8: 482.3
A9: 旭家食品股份有限公司 | B9: 轉單 | C9: 張所靜 | D9: 3300 | E9: 2640
A10: 品元實業股份有限公司 | B10: 新約寄倉 | C10: 張所靜 | D10: 31068.96 | E10: 22990.045
A11: 盛鈞國際有限公司 | B11: 轉單 | C11: 張所靜 | D11: 1080 | E11: 756
A12: 皓翰翔有限公司 | B12: 轉單 | C12: 周芃葳 | D12: 480 | E12: 336
A13: 太禓創意行銷有限公司 | B13: 轉單 | C13: 白乙君 | D13: 77375.04 | E13: 6100.8
... A271: 睿森實業有限公司 | B271: 新約寄倉 | C271: 張所靜 | D271: 475.2 | E271: 108.985

Sheet 2021-11
A1: 廠商名稱 | B1: 合作模式 | C1: 負責人 | D1: 貨款加總 | E1: 應收總和
A2: 明奇食品有限公司 | B2: 新約寄倉 | C2: 周芃葳 | D2: 61480 | E2: 47080.175
A3: 萬灃興貿易有限公司 | B3: 新約寄倉 | C3: 白乙君 | D3: 4150 | E3: 3339.5023
A4: 凱勝運動訓練有限公司 | B4: 新約寄倉 | C4: 白乙君 | D4: 1684.47 | E4: 812.2487
A5: 大誠益國際實業有限公司 | B5: 新約寄倉 | C5: 張所靜 | D5: 20266.4 | E5: 16932.785
A6: 薌園生技股份有限公司 | B6: 新約寄倉 | C6: 白乙君 | D6: 480 | E6: 282.75937
A7: 樂其國際貿易有限公司 | B7: 新約寄倉 | C7: 白乙君 | D7: 1038.4 | E7: 814.88
A8: 亞帝士運動用品 | B8: 新約寄倉 | C8: 白乙君 | D8: 9312 | E8: 7264.5519
A9: 呈芳食品行 | B9: 新約寄倉 | C9: 白乙君 | D9: 4464 | E9: 3226.395
A10: 盎谷實業有限公司 | B10: 新約寄倉 | C10: 白乙君 | D10: 492.8 | E10: 213.49528
A11: 台灣奇亞子股份有限公司 | B11: 新約寄倉 | C11: 白乙君 | D11: 9530.06 | E11: 7630.1064
A12: 先知蜂生技有限公司 | B12: 新約寄倉 | C12: 張所靜 | D12: 1568 | E12: 1136.5042
A13: 魔咕飲國際生技有限公司 | B13: 新約寄倉 | C13: 白乙君 | D13: 2875.2 | E13: 2288.6806
... A273: 聖沐生技有限公司 | B273: 新約寄倉 | C273: 謝順平 | D273: 26499.88 | E273: 21545.008
A274: 康健基因科技股份有限公司 | B274: 新約寄倉 | C274: 謝順平 | D274: 0 | E274: -105.12135 | F274: 0

Sheet 2021-12
A1: 廠商名稱 | B1: 合作模式 | C1: 負責人 | D1: 貨款加總 | E1: 應收總和 | F1: 吸收額
A2: 弗伊淨有限公司 | B2: 新約寄倉 | C2: 謝順平 | D2: 9696 | E2: 7991.73 | F2: 0
A3: 明奇食品有限公司 | B3: 新約寄倉 | C3: 周芃葳 | D3: 31916 | E3: 24439.25 | F3: 0
A4: 萬灃興貿易有限公司 | B4: 新約寄倉 | C4: 白乙君 | D4: 28757.8 | E4: 23070.956 | F4: 0
A5: 凱勝運動訓練有限公司 | B5: 新約寄倉 | C5: 白乙君 | D5: 955.2 | E5: 234.23989 | F5: 0
A6: 三福生技股份有限公司 | B6: 新約寄倉 | C6: 白乙君 | D6: 550.4 | E6: 371.49217 | F6: 0
A7: 大誠益國際實業有限公司 | B7: 新約寄倉 | C7: 張所靜 | D7: 9917.6 | E7: 8269.065 | F7: 0
A8: 錸臻賦食品行 | B8: 轉單 | C8: 白乙君 | D8: 6799 | E8: 4716.05 | F8: 0
A9: 薌園生技股份有限公司 | B9: 新約寄倉 | C9: 白乙君 | D9: 0 | E9: -75.800818 | F9: 0
A10: 樂其國際貿易有限公司 | B10: 新約寄倉 | C10: 白乙君 | D10: 188.8 | E10: 146.185 | F10: 0
A11: 小森國際有限公司 | B11: 新約寄倉 | C11: 白乙君 | D11: 0 | E11: -1.085 | F11: 0
A12: 河洛企業股份有限公司 | B12: 新約寄倉 | C12: 張所靜 | D12: 2652.7 | E12: 2072.735 | F12: 0
A13: 台山好物行 | B13: 新約寄倉 | C13: 白乙君 | D13: 0 | E13: -26.04 | F13: 0
... A278: 嘉優生技股份有限公司 | B278: 新約寄倉 | C278: 謝順平 | D278: 0 | E278: -56.42 | F278: 0
A279: 中樞生技有限公司 | B279: 新約寄倉 | C279: 謝順平 | D279: 0 | E279: -43.4
A280: 雄恆行股份有限公司 | B280: 新約寄倉 | C280: 謝順平 | D280: 751.2 | E280: 488.425 | F280: 0
A281: 芯迪國際有限公司 | B281: 新約寄倉 | C281: 謝順平 | D281: 0 | E281: -26.04 | F281: 0
A282: 寶瓏股份有限公司 | B282: 新約寄倉 | C282: 謝順平 | D282: 2464.8 | E282: 2058.725 | F282: 0
A283: 惟真國際實業有限公司 | B283: 新約寄倉 | C283: 謝順平 | D283: 3008 | E283: 2455.16 | F283: 0
A284: 良品嚴選股份有限公司 | B284: 新約寄倉 | C284: 謝順平 | D284: 0 | E284: -144.6499 | F284: 0
A285: 東祐生技顧問有限公司 | B285: 新約寄倉 | C285: 謝順平 | D285: 3019.2 | E285: 2485.235 | F285: 0
A286: 台灣優杏生物科技股份有限公司 | B286: 新約寄倉 | C286: 謝順平 | D286: 5484 | E286: 4402.52 | F286: 0
A287: 渼實有限公司 | B287: 新約寄倉 | C287: 謝順平 | D287: 588.8 | E287: 405.27955 | F287: 0
A288: 創瑞生醫股份有限公司 | B288: 新約寄倉 | C288: 張所靜 | D288: 1200 | E288: 998.02756 | F288: 0
A289: 愛上大數據股份有限公司 | B289: 轉單 | C289: 張所靜 | D289: 2370 | E289: 1659 | F289: 0
A290: 河洛企業股份有限公司 | B290: 轉單 | C290: 張所靜 | D290: 1599 | E290: 1199.25 | F290: 0
A291: 老妹的灶下有限公司 | B291: 轉單 | C291: 張所靜 | D291: 2998 | E291: 2085.61 | F291: 0
... A350: 麥思有限公司 | B350: 新約寄倉 | C350: 謝順平 | D350: 0 | E350: -35.29361 | F350: 0

Sheet 2022-01
A1: 廠商名稱 | B1: 合作模式 | C1: 負責人 | D1: 貨款加總 | E1: 貨款加總 | F1: 吸收額
A2: 佳格食品股份有限公司 | B2: 舊約寄倉 | C2: 白乙君 | D2: 16784 | E2: 14266.4 | F2: 0
A3: 禹函有限公司 | B3: 轉單 | C3: nikkihsu | D3: 205293.01 | E3: 153969.76 | F3: 0
A4: 弗伊淨有限公司 | B4: 新約寄倉 | C4: 謝順平 | D4: 0 | E4: -72.695 | F4: 0
A5: 萬灃興貿易有限公司 | B5: 新約寄倉 | C5: 白乙君 | D5: 13316.6 | E5: 10382.327 | F5: 6.56
A6: 凱勝運動訓練有限公司 | B6: 新約寄倉 | C6: 白乙君 | D6: 636.8 | E6: -20.35826 | F6: 0
A7: 三福生技股份有限公司 | B7: 新約寄倉 | C7: 白乙君 | D7: 550.4 | E7: 440.77168 | F7: 0
A8: 錸臻賦食品行 | B8: 轉單 | C8: 白乙君 | D8: 4275 | E8: 2992.5 | F8: 0
A9: 薌園生技股份有限公司 | B9: 新約寄倉 | C9: 白乙君 | D9: 0 | E9: -75.800818 | F9: 0
A10: 樂其國際貿易有限公司 | B10: 新約寄倉 | C10: 白乙君 | D10: 188.8 | E10: 125.41 | F10: 0
A11: 小森國際有限公司 | B11: 新約寄倉 | C11: 白乙君 | D11: 0 | E11: -1.085 | F11: 0
A12: 河洛企業股份有限公司 | B12: 新約寄倉 | C12: 張所靜 | D12: 8979 | E12: 7624.2 | F12: 0
A13: 老妹的灶下有限公司 | B13: 轉單 | C13: 張所靜 | D13: 3699 | E13: 2589.3 | F13: 0
... A359: 喬安企業社 | B359: 新約寄倉 | C359: joann.cheng | D359: 0 | E359: -366.49108 | F359: 0

Sheet 2022-02
A1: 廠商名稱 | B1: 合作模式 | C1: 負責人 | D1: 貨款加總 | E1: 應收總和 | F1: 吸收額
A2: 弗伊淨有限公司 | B2: 新約寄倉 | C2: 謝順平 | D2: 1112 | E2: 924.345 | F2: 0
A3: 大大小小行創股份有限公司 | B3: 新約寄倉 | C3: 許芳瑜 | D3: 0 | E3: 0 | F3: 0
A4: 俐馨企業社 | B4: 新約寄倉 | C4: nikkihsu | D4: 0 | E4: 0 | F4: 0
A5: 愛上大數據股份有限公司 | B5: 新約寄倉 | C5: 張所靜 | D5: 0 | E5: 0 | F5: 0
A6: 愛上大數據股份有限公司 | B6: 轉單 | C6: 張所靜 | D6: 0 | E6: 0 | F6: 0
A7: 大誠益國際實業有限公司 | B7: 新約寄倉 | C7: 張所靜 | D7: 20266.4 | E7: 17504.695 | F7: 0
A8: 台山好物行 | B8: 新約寄倉 | C8: nikkihsu | D8: 0 | E8: -11.76 | F8: 0
A9: 河洛企業股份有限公司 | B9: 新約寄倉 | C9: 張所靜 | D9: 11930.32 | E9: 10167.055 | F9: 0
A10: 河洛企業股份有限公司 | B10: 轉單 | C10: 張所靜 | D10: 6319 | E10: 4739.25 | F10: 0
A11: 老妹的灶下有限公司 | B11: 轉單 | C11: 張所靜 | D11: 1299 | E11: 909.3 | F11: 0
A12: 亞仕生醫科技有限公司 | B12: 新約寄倉 | C12: 謝順平 | D12: 2047.5 | E12: 1668.01 | F12: 0
A13: 萬灃興貿易有限公司 | B13: 新約寄倉 | C13: nikkihsu | D13: 14909.08 | E13: 12105.026 | F13: 0
... A449: 旺德電通股份有限公司 | B449: 轉單 | C449: 謝順平 | D449: 3069 | E449: 2465.1 | F449: 0

Sheet 2022-03
A1: 廠商名稱 | B1: 合作模式 | C1: 負責人 | D1: 貨款加總 | E1: 應收總和 | F1: 吸收額
A2: 森宏生技股份有限公司 | B2: 新約寄倉 | C2: 謝順平 | D2: 235600.77 | E2: 198685.13 | F2: 6180.8
A3: 香港商利太有限公司台灣分公司 | B3: 新約寄倉 | C3: nikkihsu | D3: 65413.48 | E3: 50895.087 | F3: 2998.74
A4: 果果堅果企業社 | B4: 新約寄倉 | C4: zoey.li | D4: 769603.47 | E4: 642055.89 | F4: 3231.2
A5: 中景科技股份有限公司 | B5: 新約寄倉 | C5: 謝順平 | D5: 11088 | E5: 9207.7326 | F5: 0
A6: 統一生機開發股份有限公司 | B6: 新約寄倉 | C6: nikkihsu | D6: 65704.92 | E6: 50500.671 | F6: 1994
A7: 三方貿易有限公司 | B7: 新約寄倉 | C7: nikkihsu | D7: 37153.48 | E7: 26742.584 | F7: 1304.8
A8: 艾絲資訊股份有限公司 | B8: 新約寄倉 | C8: eva.chang | D8: 95402.46 | E8: 77497.632 | F8: 1171.02
A9: 皮諾喬有限公司 | B9: 新約寄倉 | C9: eva.chang | D9: 69542.14 | E9: 54550.037 | F9: 1120.5
A10: 三角點品牌顧問有限公司 | B10: 新約寄倉 | C10: 謝順平 | D10: 229900.8 | E10: 198842.57 | F10: 67.2
A11: 易利信興業有限公司 | B11: 新約寄倉 | C11: zoey.li | D11: 10341.8 | E11: 8202.2168 | F11: 0
A12: 特吉國際有限公司 | B12: 新約寄倉 | C12: eva.chang | D12: 69403.94 | E12: 58116.015 | F12: 0
A13: 上寬有限公司 | B13: 新約寄倉 | C13: eva.chang | D13: 26035.35 | E13: 20551.15 | F13: 495.78
... A359: 匹塔國際股份有限公司 | B359: 新約寄倉 | C359: zoey.li | D359: 119498.4 | E359: 98980.213 | F359: 0

Sheet 2022-04
A1: 廠商名稱 | B1: 合作模式 | C1: 負責人 | D1: 貨款加總 | E1: 應收總和 | F1: 吸收額
A2: 弗伊淨有限公司 | B2: 新約寄倉 | C2: 謝順平 | D2: 2163.2 | E2: 1826.78 | F2: 0
A3: 佳格食品股份有限公司 | B3: 舊約寄倉 | C3: nikkihsu | D3: 33602 | E3: 28561.7 | F3: 0
A4: 小森國際有限公司 | B4: 新約寄倉 | C4: eva.chang | D4: 0 | E4: -0.21 | F4: 0
A5: 錸臻賦食品行 | B5: 轉單 | C5: eva.chang | D5: 3332 | E5: 2332.4 | F5: 0
A6: 大誠益國際實業有限公司 | B6: 新約寄倉 | C6: eva.chang | D6: 73325.6 | E6: 63701.325 | F6: 0
A7: 大大小小行創股份有限公司 | B7: 新約寄倉 | C7: 許芳瑜 | D7: 1486.4 | E7: 1112.305 | F7: 0
A8: 河洛企業股份有限公司 | B8: 新約寄倉 | C8: eva.chang | D8: 2424.96 | E8: 1991.78 | F8: 0
A9: 河洛企業股份有限公司 | B9: 轉單 | C9: eva.chang | D9: 7369 | E9: 5526.75 | F9: 0
A10: 老妹的灶下有限公司 | B10: 轉單 | C10: eva.chang | D10: 5928 | E10: 4149.6 | F10: 0
A11: 台山好物行 | B11: 新約寄倉 | C11: nikkihsu | D11: 0 | E11: -12.6 | F11: 0
A12: 亞仕生醫科技有限公司 | B12: 新約寄倉 | C12: 謝順平 | D12: 0 | E12: -26.25 | F12: 0
A13: 萬灃興貿易有限公司 | B13: 新約寄倉 | C13: nikkihsu | D13: 10803.28 | E13: 8887.1418 | F13: 26.5
... A356: 鮪魚肚國際行銷有限公司 | B356: 新約寄倉 | C356: 許芳瑜 | D356: 4662.64 | E356: 3497.0491 | F356: 0

Sheet 2022-05
A1: 廠商名稱 | B1: 合作模式 | C1: 負責人 | D1: 貨款加總 | E1: 應收總和 | F1: 吸收額
A2: 弗伊淨有限公司 | B2: 新約寄倉 | C2: 謝順平 | D2: 1112 | E2: 925.95 | F2: 0
A3: 大誠益國際實業有限公司 | B3: 新約寄倉 | C3: nikkihsu | D3: 125340.8 | E3: 109305.79 | F3: 49.3
A4: 蓋德國際有限公司 | B4: 新約寄倉 | C4: 謝順平 | D4: 7772.96 | E4: 6745.69 | F4: 0
A5: 愛上大數據股份有限公司 | B5: 轉單 | C5: catherine.yeh | D5: 9480 | E5: 6636 | F5: 0
A6: 大大小小行創股份有限公司 | B6: 新約寄倉 | C6: 許芳瑜 | D6: 3416 | E6: 2784.155 | F6: 0
A7: 台山好物行 | B7: 新約寄倉 | C7: nikkihsu | D7: 0 | E7: -7.98 | F7: 0
A8: 錸臻賦食品行 | B8: 轉單 | C8: catherine.yeh | D8: 10937 | E8: 7655.9 | F8: 0
A9: 亞仕生醫科技有限公司 | B9: 新約寄倉 | C9: 謝順平 | D9: 0 | E9: -21.98 | F9: 0
A10: 萬灃興貿易有限公司 | B10: 新約寄倉 | C10: nikkihsu | D10: 15467.92 | E10: 12753.801 | F10: 0
A11: 凱勝運動訓練有限公司 | B11: 新約寄倉 | C11: nikkihsu | D11: 318.4 | E11: -249.73917 | F11: 0
A12: 三福生技股份有限公司 | B12: 新約寄倉 | C12: nikkihsu | D12: 550.4 | E12: 416.41 | F12: 0
A13: 寶草園本草國際有限公司 | B13: 新約寄倉 | C13: 謝順平 | D13: 4498.4 | E13: 3719.62 | F13: 0
... A362: 佳格食品股份有限公司 | B362: 舊約寄倉 | C362: nikkihsu | D362: 23112 | E362: 19645.2 | F362: 0

Sheet 2022-06
A1: 廠商名稱 | B1: 合作模式 | C1: 負責人 | D1: 貨款加總 | E1: 應收總和 | F1: 吸收額
A2: 亞仕生醫科技有限公司 | B2: 新約寄倉 | C2: 謝順平 | D2: 0 | E2: -18.9 | F2: 0
A3: 明奇食品有限公司 | B3: 新約寄倉 | C3: nikkihsu | D3: 10541.6 | E3: 6457.04 | F3: 64
A4: 萬灃興貿易有限公司 | B4: 新約寄倉 | C4: nikkihsu | D4: 7489.9 | E4: 5892.032 | F4: 0
A5: 凱勝運動訓練有限公司 | B5: 新約寄倉 | C5: 謝順平 | D5: 955.2 | E5: 237.96787 | F5: 0
A6: 三福生技股份有限公司 | B6: 新約寄倉 | C6: nikkihsu | D6: 1100.8 | E6: 908.2 | F6: 0
A7: 大誠益國際實業有限公司 | B7: 新約寄倉 | C7: nikkihsu | D7: 77527.201 | E7: 67137.036 | F7: 0
A8: 登薾國際貿易股份有限公司 | B8: 新約寄倉 | C8: 謝順平 | D8: 160 | E8: 38.920868 | F8: 0
A9: 薌園生技股份有限公司 | B9: 新約寄倉 | C9: nikkihsu | D9: 0 | E9: -57.520081 | F9: 0
A10: 樂其國際貿易有限公司 | B10: 新約寄倉 | C10: nikkihsu | D10: 0 | E10: -4.2 | F10: 0
A11: 河洛企業股份有限公司 | B11: 新約寄倉 | C11: catherine.yeh | D11: 15962.12 | E11: 13674.225 | F11: -1.8189894e-12
A12: 亞帝士運動用品 | B12: 新約寄倉 | C12: 周芃葳 | D12: 6813.6 | E12: 5471.27 | F12: 0
A13: 呈芳食品行 | B13: 新約寄倉 | C13: catherine.yeh | D13: 8208 | E13: 5972.3206 | F13: 0
... A177: 啡翔白咖啡坊有限公司 | B177: 新約寄倉 | C177: catherine.yeh | D177: 0 | E177: -9.3076655 | F177: 0
A178: 動健康有限公司 | B178: 新約寄倉 | C178: zoey.li | E178: 13092.262 | F178: 0
A179: 凱勝運動行銷有限公司 | B179: 新約寄倉 | C179: zoey.li | D179: 33773.74 | E179: 27965.185 | F179: 0
A180: 拌伴餐飲有限公司 | B180: 新約寄倉 | C180: catherine.yeh | D180: 0 | E180: -10.5 | F180: 0
A181: 唐承健康事業有限公司 | B181: 新約寄倉 | C181: 謝順平 | D181: 0 | E181: -19.426737 | F181: 0
A182: 鴻懿企業有限公司 | B182: 新約寄倉 | C182: 周芃葳 | D182: 4976.8 | E182: 4064.1208 | F182: 0
A183: 團時有限公司 | B183: 新約寄倉 | C183: catherine.yeh | D183: 0 | E183: -30.598965 | F183: 0
A184: 婕沛國際企業有限公司 | B184: 新約寄倉 | C184: catherine.yeh | D184: 0 | E184: -65.694243 | F184: 0
A185: 邁界有限公司 | B185: 新約寄倉 | C185: catherine.yeh | D185: 8549.62 | E185: 6835.4626 | F185: 0
A186: 晧晟股份有限公司 | B186: 新約寄倉 | C186: zoey.li | D186: 0 | E186: -4.3773068 | F186: 0
A187: 愛達科技有限公司 | B187: 新約寄倉 | C187: catherine.yeh | D187: 0 | E187: -28.35 | F187: 0
A188: 觀薇生醫有限公司 | B188: 新約寄倉 | C188: 謝順平 | D188: 2528 | E188: 2210.255 | F188: 0
A189: 一樂鶴股份有限公司 | B189: 新約寄倉 | C189: 謝順平 | D189: 7936.8 | E189: 6632.1929 | F189: 0
A190: 永恆世成有限公司 | B190: 新約寄倉 | C190: nikkihsu | D190: 11759.2 | E190: 8820.2706 | F190: 64
... A343: 鈞嵐企業有限公司 | B343: 轉單 | C343: eva.chang | D343: 1227 | E343: 858.9 | F343: 0

Sheet 2022-07
A1: 廠商名稱 | B1: 合作模式 | C1: 負責人 | D1: 貨款加總 | E1: 應收總和 | F1: 吸收額
A2: 柏立奧有限公司 | B2: 新約寄倉 | C2: zoey.li | D2: 84691.73 | E2: 71821.75 | F2: 7.2759576e-12
A3: 三角點品牌顧問有限公司 | B3: 新約寄倉 | C3: joann.cheng | D3: 190483 | E3: 165718.05 | F3: 1.1823431e-11
A4: 奕瑪國際行銷股份有限公司 | B4: 新約寄倉 | C4: zoey.li | D4: 66579.85 | E4: 57063.08 | F4: -5.4569682e-12
A5: 友伴生活有限公司 | B5: 新約寄倉 | C5: joann.cheng | D5: 306.2 | E5: 182.91 | F5: 0
A6: 果果堅果企業社 | B6: 新約寄倉 | C6: zoey.li | D6: 716138.32 | E6: 599851.71 | F6: 369.21
A7: 果果堅果企業社 | B7: 轉單 | C7: zoey.li | D7: 12189.001 | E7: 8532.3004 | F7: 0
A8: 沛裕實業有限公司 | B8: 新約寄倉 | C8: joann.cheng | D8: 71104.67 | E8: 56574.51 | F8: -4.5474735e-12
A9: 偉儒國際有限公司 | B9: 新約寄倉 | C9: 周芃葳 | D9: 9405.24 | E9: 7686.54 | F9: 1.39
A10: 自然思維股份有限公司 | B10: 新約寄倉 | C10: catherine.yeh | D10: 42330.171 | E10: 35691.581 | F10: 1.8189894e-12
A11: 廣紘國際股份有限公司 | B11: 新約寄倉 | C11: nikkihsu | D11: 92802.83 | E11: 75745.99 | F11: 207.12
A13: 悠活原力股份有限公司 | B13: 新約寄倉 | C13: joann.cheng | D13: 21302.27 | E13: 17934.76 | F13: 4.5474735e-13
A14: 寰宇生物科技股份有限公司 | B14: 新約寄倉 | C14: joann.cheng | D14: 25652.663 | E14: 21275.423 | F14: -1.1368684e-12
... A314: 森宏生技股份有限公司 | B314: 新約寄倉 | C314: joann.cheng | D314: 216558.45 | E314: 185329.97 | F314: 5.4569682e-12

Sheet 2022-08
A1: 廠商名稱 | B1: 合作模式 | C1: 負責人 | D1: 貨款加總 | E1: 應收總和 | F1: 吸收額
A2: 樂芯生技有限公司 | B2: 新約寄倉 | C2: joann.cheng | D2: 0 | E2: -5.25 | F2: 0
A3: 大誠益國際實業有限公司 | B3: 新約寄倉 | C3: nikkihsu | D3: 111649.4 | E3: 98915.724 | F3: 27.3328
A4: 愛上大數據股份有限公司 | B4: 轉單 | C4: catherine.yeh | D4: 2370 | E4: 1659 | F4: 0
A5: 丹帝洋行有限公司 | B5: 新約寄倉 | C5: nikkihsu | D5: 5672.8 | E5: 4613.75 | F5: 0
A6: 蓋德國際有限公司 | B6: 新約寄倉 | C6: joann.cheng | D6: 3694.08 | E6: 2971.52 | F6: 0
A7: 弗伊淨有限公司 | B7: 新約寄倉 | C7: joann.cheng | D7: 1112 | E7: 949.71 | F7: 0
A8: 凱勝運動訓練有限公司 | B8: 新約寄倉 | C8: joann.cheng | D8: 0 | E8: -440.2 | F8: 0
A9: 錸臻賦食品行 | B9: 轉單 | C9: catherine.yeh | D9: 4807 | E9: 3364.9 | F9: 0
A10: 大大小小行創股份有限公司 | B10: 新約寄倉 | C10: joann.cheng | D10: 814.4 | E10: 490.03 | F10: 0
A11: 萬灃興貿易有限公司 | B11: 新約寄倉 | C11: nikkihsu | D11: 10036.98 | E11: 9487.48 | F11: 0
A12: 三福生技股份有限公司 | B12: 新約寄倉 | C12: nikkihsu | D12: 0 | E12: -12.88 | F12: 0
A13: 寶草園本草國際有限公司 | B13: 新約寄倉 | C13: joann.cheng | D13: 16458.4 | E13: 14067.24 | F13: 0
... A309: 艾絲資訊股份有限公司 | B309: 新約寄倉 | C309: catherine.yeh | D309: 71948 | E309: 71942.49 | F309: 0

Sheet 2022-09
A1: 廠商名稱 | B1: 合作模式 | C1: 負責人 | D1: 貨款加總 | E1: 應收總和 | F1: 吸收額
A2: 饌元有限公司 | B2: 轉單 | C2: 楊若莉 | D2: 1333676.4 | E2: 1333676.4 | F2: 0
A3: 果果堅果企業社 | B3: 新約寄倉 | C3: Jacob Pan | D3: 1036978 | E3: 858572.23 | F3: 5554.4
A4: 樂維根有限公司 | B4: 新約寄倉 | C4: zoey.li | D4: 525735.47 | E4: 420303.76 | F4: 1.1641532e-10
A5: 禹函有限公司 | B5: 轉單 | C5: nikkihsu | D5: 444285.15 | E5: 333213.86 | F5: 0
A6: 森宏生技股份有限公司 | B6: 新約寄倉 | C6: Jacob Pan | D6: 196502.24 | E6: 164773.46 | F6: 3985.2
A7: 健生活股份有限公司 | B7: 新約寄倉 | C7: Jacob Pan | D7: 183456.8 | E7: 158509.31 | F7: 475.2
A8: 青荷國際有限公司 | B8: 新約寄倉 | C8: catherine.yeh | D8: 141890.11 | E8: 107024.24 | F8: 215.66
A9: 廣紘國際股份有限公司 | B9: 新約寄倉 | C9: nikkihsu | D9: 113768.92 | E9: 91219.25 | F9: 103.32
A10: 奕瑪國際行銷股份有限公司 | B10: 新約寄倉 | C10: zoey.li | D10: 110724 | E10: 89720.1 | F10: 0
A11: 柏立奧有限公司 | B11: 新約寄倉 | C11: Jacob Pan | D11: 100153.63 | E11: 79652.908 | F11: 0
A12: 大誠益國際實業有限公司 | B12: 新約寄倉 | C12: nikkihsu | D12: 90334.4 | E12: 77489.77 | F12: 0
A13: 沛裕實業有限公司 | B13: 新約寄倉 | C13: joann.cheng | D13: 102945.84 | E13: 77214.58 | F13: 0
... A296: 河洛企業股份有限公司 | B296: 轉單 | C296: catherine.yeh | D296: 1574 | E296: 1574 | F296: 0

Sheet 2022-10
A1: 廠商名稱 | B1: 合作模式 | C1: 負責人 | D1: 貨款加總 | E1: 應收總和 | F1: 吸收額
A2: 明奇食品有限公司 | B2: 新約寄倉 | C2: catherine.yeh | D2: 11122.4 | E2: 8503.92 | F2: 0
A3: 愛上大數據股份有限公司 | B3: 轉單 | C3: catherine.yeh | D3: 7110 | E3: 4977 | F3: 0
A4: 大誠益國際實業有限公司 | B4: 新約寄倉 | C4: catherine.yeh | D4: 52416.001 | E4: 44426.091 | F4: 23.73312
A5: 錸臻賦食品行 | B5: 轉單 | C5: catherine.yeh | D5: 4030 | E5: 2821 | F5: 0
A6: 登薾國際貿易股份有限公司 | B6: 新約寄倉 | C6: joann.cheng | D6: 15480 | E6: 13082.69 | F6: 0
A7: 河洛企業股份有限公司 | B7: 新約寄倉 | C7: catherine.yeh | D7: 12221.2 | E7: 12112.09 | F7: 0
A8: 河洛企業股份有限公司 | B8: 轉單 | C8: catherine.yeh | D8: 1989 | E8: 1491.75 | F8: 0
A9: 老妹的灶下有限公司 | B9: 轉單 | C9: catherine.yeh | D9: 550 | E9: 385 | F9: 0
A10: 亞帝士運動用品 | B10: 新約寄倉 | C10: 周芃葳 | D10: 16080 | E10: 13110.52 | F10: 0
A11: 寶齡富錦生技股份有限公司 | B11: 新約寄倉 | C11: joann.cheng | D11: 1944 | E11: 1568.6 | F11: 0
A12: 台灣奇亞子股份有限公司 | B12: 新約寄倉 | C12: catherine.yeh | D12: 7758.84 | E12: 6301.79 | F12: 0
A13: 魔咕飲國際生技有限公司 | B13: 新約寄倉 | C13: catherine.yeh | D13: 0 | E13: -41.85 | F13: 0
... A303: 盛禾生醫國際事業有限公司 | B303: 轉單 | C303: Jacob Pan | D303: 586 | E303: 586 | F303: 0

Sheet 2022-11
A1: 廠商名稱 | B1: 合作模式 | C1: 負責人 | D1: 貨款加總 | E1: 應收總和 | F1: 吸收額
A2: 明奇食品有限公司 | B2: 新約寄倉 | C2: catherine.yeh | D2: 11022.8 | E2: 8476 | F2: 0
A3: 萬灃興貿易有限公司 | B3: 新約寄倉 | C3: catherine.yeh | D3: 87.2 | E3: 49.41 | F3: 0
A4: 愛上大數據股份有限公司 | B4: 轉單 | C4: catherine.yeh | D4: 2370 | E4: 1659 | F4: 0
A5: 大誠益國際實業有限公司 | B5: 新約寄倉 | C5: catherine.yeh | D5: 54243.201 | E5: 45839.501 | F5: 0
A6: 錸臻賦食品行 | B6: 轉單 | C6: catherine.yeh | D6: 3332 | E6: 2304.19 | F6: 0
A7: 登薾國際貿易股份有限公司 | B7: 新約寄倉 | C7: joann.cheng | D7: 15840 | E7: 13303.46 | F7: 0
A8: 河洛企業股份有限公司 | B8: 新約寄倉 | C8: catherine.yeh | D8: 789.58 | E8: 578.09 | F8: 0
A9: 河洛企業股份有限公司 | B9: 轉單 | C9: catherine.yeh | D9: 1599 | E9: 1199.25 | F9: 0
A10: 老妹的灶下有限公司 | B10: 轉單 | C10: catherine.yeh | D10: 2699 | E10: 1882.31 | F10: 0
A11: 亞帝士運動用品 | B11: 新約寄倉 | C11: 周芃葳 | D11: 17116.8 | E11: 13789.39 | F11: 0
A12: 呈芳食品行 | B12: 新約寄倉 | C12: catherine.yeh | D12: 2016 | E12: 1457.76 | F12: 0
A13: 寶齡富錦生技股份有限公司 | B13: 新約寄倉 | C13: joann.cheng | D13: 3288 | E13: 2620.23 | F13: 0
... A314: 鉅旺國際股份有限公司 | B314: 新約寄倉 | C314: joann.cheng | D314: 2899 | E314: 2899 | F314: 0

Sheet 2022-12
A1: 廠商名稱 | B1: 合作模式 | C1: 負責人 | D1: 貨款加總 | E1: 應收總和 | F1: 吸收額
A2: 明奇食品有限公司 | B2: 新約寄倉 | C2: catherine.yeh | D2: 18734.4 | E2: 14410.3 | F2: 0
A3: 萬灃興貿易有限公司 | B3: 新約寄倉 | C3: catherine.yeh | D3: 5351.15 | E3: 4324.56 | F3: -4.7295501e-13
A4: 愛上大數據股份有限公司 | B4: 轉單 | C4: catherine.yeh | D4: 4740 | E4: 3318 | F4: 0
A5: 大誠益國際實業有限公司 | B5: 新約寄倉 | C5: catherine.yeh | D5: 49074.402 | E5: 42153.662 | F5: 5.93328
A6: 錸臻賦食品行 | B6: 轉單 | C6: catherine.yeh | D6: 5413 | E6: 3782.12 | F6: 0
A7: 登薾國際貿易股份有限公司 | B7: 新約寄倉 | C7: joann.cheng | D7: 4560 | E7: 3822.37 | F7: 0
A8: 河洛企業股份有限公司 | B8: 新約寄倉 | C8: catherine.yeh | D8: 0 | E8: -51.77 | F8: 0
A9: 老妹的灶下有限公司 | B9: 轉單 | C9: catherine.yeh | D9: 3996 | E9: 2790.21 | F9: 0
A10: 亞帝士運動用品 | B10: 新約寄倉 | C10: 周芃葳 | D10: 8863.2 | E10: 7185.6 | F10: 0
A11: 呈芳食品行 | B11: 新約寄倉 | C11: catherine.yeh | D11: 3168 | E11: 2140.96 | F11: 0
A12: 寶齡富錦生技股份有限公司 | B12: 新約寄倉 | C12: joann.cheng | D12: 1344 | E12: 1029.99 | F12: 0
A13: 台灣奇亞子股份有限公司 | B13: 新約寄倉 | C13: catherine.yeh | D13: 21755.17 | E13: 21682.23 | F13: 0
... A293: 珍桂生物科技有限公司 | B293: 新約寄倉 | C293: catherine.yeh | D293: 345 | E293: 345 | F293: 0

Sheet 2023-01
A1: 廠商名稱 | B1: 合作模式 | C1: 負責人 | D1: 貨款加總 | E1: 應收總和 | F1: 吸收額
A2: 明奇食品有限公司 | B2: 新約寄倉 | C2: catherine.yeh | D2: 39743.2 | E2: 32080.07 | F2: 146.4
A3: 萬灃興貿易有限公司 | B3: 新約寄倉 | C3: catherine.yeh | D3: 4860.59 | E3: 3913.67 | F3: 2.5446312e-13
A4: 大誠益國際實業有限公司 | B4: 新約寄倉 | C4: catherine.yeh | D4: 19816.001 | E4: 17099.191 | F4: 53.39952
A5: 錸臻賦食品行 | B5: 轉單 | C5: catherine.yeh | D5: 3627 | E5: 2538.9 | F5: 0
A6: 登薾國際貿易股份有限公司 | B6: 新約寄倉 | C6: joann.cheng | D6: 5240 | E6: 4443.14 | F6: 0
A7: 河洛企業股份有限公司 | B7: 新約寄倉 | C7: catherine.yeh | D7: 1165.2 | E7: 976.66 | F7: 0
A8: 河洛企業股份有限公司 | B8: 轉單 | C8: catherine.yeh | D8: 2099 | E8: 1574.25 | F8: 0
A9: 老妹的灶下有限公司 | B9: 轉單 | C9: catherine.yeh | D9: 3958 | E9: 2770.6 | F9: 0
A10: 亞帝士運動用品 | B10: 新約寄倉 | C10: 周芃葳 | D10: 6063.2 | E10: 4990.13 | F10: 0
A11: 呈芳食品行 | B11: 新約寄倉 | C11: catherine.yeh | D11: 5126.4 | E11: 3930.01 | F11: 0
A12: 寶齡富錦生技股份有限公司 | B12: 新約寄倉 | C12: joann.cheng | D12: 1872 | E12: 1478.2 | F12: 0
A13: 台灣奇亞子股份有限公司 | B13: 新約寄倉 | C13: catherine.yeh | D13: 0 | E13: -60.28 | F13: 0
... A290: 台劦企業股份有限公司 | B290: 轉單 | C290: joann.cheng | D290: 2800 | E290: 2800 | F290: 0

Sheet 2023-02
A1: 廠商名稱 | B1: 合作模式 | C1: 負責人 | D1: 貨款加總 | E1: 應收總和 | F1: 吸收額
A2: 明奇食品有限公司 | B2: 新約寄倉 | C2: catherine.yeh | D2: 36692.8 | E2: 29080.29 | F2: 0
A3: 萬灃興貿易有限公司 | B3: 新約寄倉 | C3: catherine.yeh | D3: 10824.58 | E3: 8896.7701 | F3: 0
A4: 愛上大數據股份有限公司 | B4: 轉單 | C4: catherine.yeh | D4: 2370 | E4: 1659 | F4: 0
A5: 大誠益國際實業有限公司 | B5: 新約寄倉 | C5: catherine.yeh | D5: 63597.603 | E5: 55331.393 | F5: 0
A6: 錸臻賦食品行 | B6: 轉單 | C6: catherine.yeh | D6: 3877 | E6: 2713.9 | F6: 0
A7: 登薾國際貿易股份有限公司 | B7: 新約寄倉 | C7: joann.cheng | D7: 8000 | E7: 6927.76 | F7: 0
A8: 河洛企業股份有限公司 | B8: 新約寄倉 | C8: catherine.yeh | D8: 799.2 | E8: 656.46 | F8: 0
A9: 河洛企業股份有限公司 | B9: 轉單 | C9: catherine.yeh | D9: 3198 | E9: 2398.5 | F9: 0
A10: 老妹的灶下有限公司 | B10: 轉單 | C10: catherine.yeh | D10: 4307 | E10: 3014.9 | F10: 0
A11: 亞帝士運動用品 | B11: 新約寄倉 | C11: 周芃葳 | D11: 5374.4 | E11: 4368.27 | F11: 0
A12: 呈芳食品行 | B12: 新約寄倉 | C12: catherine.yeh | D12: 1728 | E12: 1298.29 | F12: 0
A13: 寶齡富錦生技股份有限公司 | B13: 新約寄倉 | C13: joann.cheng | D13: 1591.2 | E13: 1324.14 | F13: 0
... A270: 逆風飛翔股份有限公司 | B270: 新約寄倉 | C270: joann.cheng | D270: 400 | E270: 400 | F270: 0

Sheet 2023-03
A1: 廠商名稱 | B1: 合作模式 | C1: 負責人 | D1: 貨款加總 | E1: 應收總和 | F1: 吸收額
A2: 明奇食品有限公司 | B2: 新約寄倉 | C2: catherine.yeh | D2: 65627.2 | E2: 52308.18 | F2: 0
A3: 萬灃興貿易有限公司 | B3: 新約寄倉 | C3: catherine.yeh | D3: 41247.12 | E3: 34084.12 | F3: 9.6
A4: 大誠益國際實業有限公司 | B4: 新約寄倉 | C4: catherine.yeh | D4: 100011.2 | E4: 86783.001 | F4: 5.93328
A5: 錸臻賦食品行 | B5: 轉單 | C5: catherine.yeh | D5: 3179 | E5: 2225.3 | F5: 0
A6: 登薾國際貿易股份有限公司 | B6: 新約寄倉 | C6: joann.cheng | D6: 15200 | E6: 13235.39 | F6: 0
A7: 老妹的灶下有限公司 | B7: 轉單 | C7: catherine.yeh | D7: 1299 | E7: 909.3 | F7: 0
A8: 亞帝士運動用品 | B8: 新約寄倉 | C8: 周芃葳 | D8: 6784 | E8: 5558.76 | F8: 0
A9: 呈芳食品行 | B9: 新約寄倉 | C9: ㄑ | D9: 9000 | E9: 6893.63 | F9: 0
A10: 寶齡富錦生技股份有限公司 | B10: 新約寄倉 | C10: joann.cheng | D10: 4616.8 | E10: 3892.74 | F10: 0
A11: 台灣奇亞子股份有限公司 | B11: 新約寄倉 | C11: catherine.yeh | D11: 0 | E11: -89.59 | F11: 0
A12: 百歐新創食品科技有限公司 | B12: 轉單 | C12: catherine.yeh | D12: 940 | E12: 658 | F12: 0
A13: 魔咕飲國際生技有限公司 | B13: 新約寄倉 | C13: catherine.yeh | D13: 0 | E13: -52.08 | F13: 0
... A250: 琪祥國際有限公司 | B250: 轉單 | C250: catherine.yeh | D250: 600 | E250: 600 | F250: 0
A251: 果利生技有限公司 | B251: 轉單合約 | C251: vivi.huang | D251: 5311 | E251: 1222 | F251: 0 | G251: 106 | H251: 425 | I251: 0 | J251: 0 | K251: 0 | L251: 0 | M251: 0 | N251: https://docs.google.com/spreadsheets/d/1oVg9zHv-3sNnyYrmd58_gSKdzwNVIDiOoG3jzhpF8UA

Sheet 2023-04
A1: 廠商名稱 | B1: 合作模式 | C1: 負責人 | D1: 貨款加總 | E1: 應收總和 | F1: 吸收額
A2: 明奇食品有限公司 | B2: 新約寄倉 | C2: catherine.yeh | D2: 33792 | E2: 26508.73 | F2: 0
A3: 萬灃興貿易有限公司 | B3: 新約寄倉 | C3: catherine.yeh | D3: 44161.02 | E3: 36344 | F3: 31.9
A4: 大誠益國際實業有限公司 | B4: 新約寄倉 | C4: catherine.yeh | D4: 66883.203 | E4: 58174.433 | F4: 5.46656
A5: 登薾國際貿易股份有限公司 | B5: 新約寄倉 | C5: vivi.huang | D5: 4000 | E5: 3437.68 | F5: 0
A6: 亞帝士運動用品 | B6: 新約寄倉 | C6: 周芃葳 | D6: 4654.4 | E6: 3791.67 | F6: 0
A7: 呈芳食品行 | B7: 新約寄倉 | C7: catherine.yeh | D7: 3240 | E7: 2289.6 | F7: 0
A8: 寶齡富錦生技股份有限公司 | B8: 新約寄倉 | C8: vivi.huang | D8: 6490.4 | E8: 6052.24 | F8: -4.5474735e-13
A9: 台灣奇亞子股份有限公司 | B9: 新約寄倉 | C9: catherine.yeh | D9: 0 | E9: -86.7 | F9: 0
A10: 魔咕飲國際生技有限公司 | B10: 新約寄倉 | C10: catherine.yeh | D10: 0 | E10: -50.4 | F10: 0
A11: 魔咕飲國際生技有限公司 | B11: 轉單 | C11: catherine.yeh | D11: 3147 | E11: 2202.9 | F11: 0
A12: 鑫欣羿股份有限公司 | B12: 新約寄倉 | C12: catherine.yeh | D12: 81432.914 | E12: 68607.684 | F12: 22.458282
A13: 柏立奧有限公司 | B13: 新約寄倉 | C13: vivi.huang | D13: 159259.05 | E13: 129941.34 | F13: 0
... A234: 黃董創藝實業有限公司 | B234: 轉單 | C234: ashley.lin | D234: 896 | E234: 896 | F234: 0

Sheet 2023-05
A1: 廠商名稱 | B1: 合作模式 | C1: 負責人 | D1: 貨款加總 | E1: 應收總和 | F1: 吸收額
A2: 明奇食品有限公司 | B2: 新約寄倉 | C2: catherine.yeh | D2: 67067.2 | E2: 53886.05 | F2: 8.8
A3: 萬灃興貿易有限公司 | B3: 新約寄倉 | C3: catherine.yeh | D3: 61632.1 | E3: 50865.66 | F3: 0
A4: 大誠益國際實業有限公司 | B4: 新約寄倉 | C4: catherine.yeh | D4: 145064.01 | E4: 126955.75 | F4: 5.93328
A5: 錸臻賦食品行 | B5: 轉單 | C5: catherine.yeh | D5: 3764 | E5: 2634.8 | F5: 0
A6: 登薾國際貿易股份有限公司 | B6: 新約寄倉 | C6: vivi.huang | D6: 13280 | E6: 11399.4 | F6: 0
A7: 老妹的灶下有限公司 | B7: 轉單 | C7: catherine.yeh | D7: 3239 | E7: 2267.3 | F7: 0
A8: 亞帝士運動用品 | B8: 新約寄倉 | C8: 周芃葳 | D8: 5423.2 | E8: 4385.36 | F8: 0
A9: 呈芳食品行 | B9: 新約寄倉 | C9: catherine.yeh | D9: 9072 | E9: 6842.08 | F9: 0
A10: 寶齡富錦生技股份有限公司 | B10: 新約寄倉 | C10: vivi.huang | D10: 9376.8 | E10: 7921.77 | F10: 0
A11: 台灣奇亞子股份有限公司 | B11: 新約寄倉 | C11: catherine.yeh | D11: 0 | E11: -88.85 | F11: 0
A12: 魔咕飲國際生技有限公司 | B12: 新約寄倉 | C12: catherine.yeh | D12: 806.4 | E12: 607.73 | F12: 0
A13: 魔咕飲國際生技有限公司 | B13: 轉單 | C13: catherine.yeh | D13: 2016 | E13: 1411.2 | F13: 0
... A226: 駿霈國際有限公司 | B226: 轉單 | C226: 白乙君 | D226: 1199 | E226: 1199 | F226: 0

Sheet 2023-06
A1: 廠商名稱 | B1: 合作模式 | C1: 負責人 | D1: 貨款加總 | E1: 應收總和 | F1: 吸收額
A2: 明奇食品有限公司 | B2: 新約寄倉 | C2: catherine.yeh | D2: 41747.2 | E2: 32936.61 | F2: 0
A3: 萬灃興貿易有限公司 | B3: 新約寄倉 | C3: catherine.yeh | D3: 32660 | E3: 26550.73 | F3: 3.2
A4: 大誠益國際實業有限公司 | B4: 新約寄倉 | C4: catherine.yeh | D4: 44787.201 | E4: 39004.091 | F4: 10.93312
A5: 錸臻賦食品行 | B5: 轉單 | C5: catherine.yeh | D5: 8405 | E5: 5883.5 | F5: 0
A6: 登薾國際貿易股份有限公司 | B6: 新約寄倉 | C6: vivi.huang | D6: 8680 | E6: 7561.08 | F6: 0
A7: 亞帝士運動用品 | B7: 新約寄倉 | C7: 周芃葳 | D7: 6228 | E7: 4895.49 | F7: 0
A8: 呈芳食品行 | B8: 新約寄倉 | C8: catherine.yeh | D8: 5443.2 | E8: 3920.38 | F8: 0
A9: 寶齡富錦生技股份有限公司 | B9: 新約寄倉 | C9: vivi.huang | D9: 8004 | E9: 6644.86 | F9: 0
A10: 台灣奇亞子股份有限公司 | B10: 新約寄倉 | C10: catherine.yeh | D10: 0 | E10: -64.5 | F10: 0
A11: 百歐新創食品科技有限公司 | B11: 轉單 | C11: catherine.yeh | D11: 800 | E11: 560 | F11: 0
A12: 魔咕飲國際生技有限公司 | B12: 新約寄倉 | C12: catherine.yeh | D12: 0 | E12: -44.1 | F12: 0
A13: 魔咕飲國際生技有限公司 | B13: 轉單 | C13: catherine.yeh | D13: 2880 | E13: 2016 | F13: 0
... A217: 芮斯特有限公司 | B217: 新約寄倉 | C217: vivi.huang | D217: 3231.69 | E217: 2732.28 | F217: 0

Sheet 2023-07(89錯誤)
A1: 廠商名稱 | B1: 合作模式 | C1: 負責人 | D1: 銷售總額 | E1: 抽成 | F1: 平台維護費 | G1: 金流處理費 | H1: 行銷推廣費 | I1: 活動贊助費 | J1: 訂單處理費 | K1: 運費攤提 | L1: 吸收額 | M1: 報表連結
A2: 愛上大數據股份有限公司 | B2: 轉單合約 | C2: catherine.yeh | D2: 4740 | E2: 948 | F2: 0 | G2: 95 | H2: 379 | I2: 0 | J2: 0 | K2: 0 | L2: 3792 | M2: https://docs.google.com/spreadsheets/d/1OnQ6SLJANgfBLM5_6dIRX-RWP-MTTc7sfl8lYzZiRgY
A3: 大誠益國際實業有限公司 | B3: 寄倉新約 | C3: catherine.yeh | D3: 52615 | E3: 10523 | F3: 263 | G3: 1052 | H3: 1841 | I3: 1315 | J3: 450 | K3: 447 | L3: 0 | M3: https://docs.google.com/spreadsheets/d/1uP2FYqWSRQs9idDxInBcw6iYckaO6r7i_7Ettp2-0vs
A4: 錸臻賦食品行 | B4: 轉單合約 | C4: catherine.yeh | D4: 6639 | E4: 1328 | F4: 0 | G4: 133 | H4: 531 | I4: 0 | J4: 0 | K4: 0 | L4: 5311 | M4: https://docs.google.com/spreadsheets/d/1kQUcmKu2VKQEyL_H44mUlC9mG-oCNX0ydbIWGzU7lJk
A5: 明奇食品有限公司 | B5: 寄倉新約 | C5: catherine.yeh | D5: 37537 | E5: 7507 | F5: 187 | G5: 750 | H5: 1313 | I5: 939 | J5: 1280 | K5: 901 | L5: 0 | M5: https://docs.google.com/spreadsheets/d/1YH4p5MPBySx9lBSJqMPDvlaPGIOpMkBblyqcbwm3xN0
A6: 登薾國際貿易股份有限公司 | B6: 寄倉新約 | C6: vivi.huang | D6: 7100 | E6: 1420 | F6: 36 | G6: 142 | H6: 249 | I6: 178 | J6: 13 | K6: 135 | L6: 0 | M6: https://docs.google.com/spreadsheets/d/1xqe0sEiqLsVU9GtxkEo2GSYHavRmNg0AAd6qOac2Z-s
A7: 萬灃興貿易有限公司 | B7: 寄倉新約 | C7: catherine.yeh | D7: 37455 | E7: 7695 | F7: 185 | G7: 748 | H7: 1310 | I7: 936 | J7: 306 | K7: 1583 | L7: 7 | M7: https://docs.google.com/spreadsheets/d/1JSyons7JUyAqtECbpa1TWIZSyQCjHFTsfbgOMcry_OA
A8: 亞帝士運動用品 | B8: 寄倉新約 | C8: 周芃葳 | D8: 1979 | E8: 396 | F8: 9 | G8: 40 | H8: 69 | I8: 49 | J8: 15 | K8: 17 | L8: 0 | M8: https://docs.google.com/spreadsheets/d/1qAN7o47Y8iuS_fp2yLmYqxgZwx3v_wWGITqwYqueB6Y
A9: 呈芳食品行 | B9: 寄倉新約 | C9: catherine.yeh | D9: 4374 | E9: 875 | F9: 22 | G9: 87 | H9: 153 | I9: 109 | J9: 135 | K9: 305 | L9: 0 | M9: https://docs.google.com/spreadsheets/d/1TV2-2kCWldeDp_-UT2fEWPua75KOCXt1Q7-9FT2iFro
A10: 寶齡富錦生技股份有限公司 | B10: 寄倉新約 | C10: vivi.huang | D10: 13476 | E10: 2695 | F10: 68 | G10: 270 | H10: 473 | I10: 338 | J10: 280 | K10: 161 | L10: 0 | M10: https://docs.google.com/spreadsheets/d/1odWE6A1q9sfIZWoG0rdzOwZOkJRtUQjvdOyPs7Ozkt4
A11: 台灣奇亞子股份有限公司 | B11: 寄倉新約 | C11: catherine.yeh | D11: 0 | E11: 0 | F11: 0 | G11: 0 | H11: 0 | I11: 0 | J11: 0 | K11: 0 | L11: 0 | M11: https://docs.google.com/spreadsheets/d/19DF0ijQUbSJp6VfjRoD1Du3NYSiDJG9xrQyhFHnmgnY
A12: 魔咕飲國際生技有限公司 | B12: 寄倉新約 | C12: catherine.yeh | D12: 0 | E12: 0 | F12: 0 | G12: 0 | H12: 0 | I12: 0 | J12: 0 | K12: 0 | L12: 0 | M12: https://docs.google.com/spreadsheets/d/1xPINU6eHTUEWdQ8tf8s9mca_bwWOHLkxpIjyzAgl29M
A13: 魔咕飲國際生技有限公司 | B13: 轉單合約 | C13: catherine.yeh | D13: 1440 | E13: 288 | F13: 0 | G13: 29 | H13: 115 | I13: 0 | J13: 0 | K13: 0 | L13: 1152 | M13: https://docs.google.com/spreadsheets/d/1OQSPM5zEN9D175z6-bVa0ZkisKUmK9Ji8td-Mg78HDQ
... A213: 聖倪國際有限公司 | B213: 寄倉新約 | C213: catherine.yeh | D213: 0 | E213: 0 | F213: 0 | G213: 0 | H213: 0 | I213: 0 | J213: 0 | K213: 0 | L213: 0 | M213: https://docs.google.com/spreadsheets/d/1PB01jgEUA5dom2l7t24MBQE_JS_G_EYLtWfjOkotVsE

Sheet 2023-07
A1: 廠商名稱 | B1: 合作模式 | C1: 負責人 | D1: 銷售總額 | E1: 抽成 | F1: 平台維護費 | G1: 金流處理費 | H1: 行銷推廣費 | I1: 活動贊助費 | J1: 訂單處理費 | K1: 運費攤提 | L1: 人工處理費 | M1: 倉租加總 | N1: 吸收額 | O1: 報表連結 | R1: {=INDEX('2023-07(89錯誤)'!$D:$D, MATCH(1, ('2023-07(89錯誤)'!$A:$A=A1)*('2023-07(89錯誤)'!$B:$B=B1), 0))} -> 銷售總額 | S1: 差異金額
A2: 健生活股份有限公司 | B2: 寄倉新約 | C2: vivi.huang | D2: 317683 | E2: 63537 | F2: 1589 | G2: 6350 | H2: 11122 | I2: 7947 | J2: 2910 | K2: 4841 | L2: 2910 | M2: 4017 | N2: 0 | O2: https://docs.google.com/spreadsheets/d/1hMujVVjXcAlHayPGbfHgl4_SU_S9rX9bfkaKjkpeghI | R2: {=INDEX('2023-07(89錯誤)'!$D:$D, MATCH(1, ('2023-07(89錯誤)'!$A:$A=A2)*('2023-07(89錯誤)'!$B:$B=B2), 0))} -> 1271321 | S2: =R2-D2 -> 953638
A3: 森宏生技股份有限公司 | B3: 寄倉新約 | C3: vivi.huang | D3: 201690 | E3: 38252 | F3: 1008 | G3: 4039 | H3: 7061 | I3: 5045 | J3: 3995 | K3: 2499 | L3: 3995 | M3: 1005 | N3: 0 | O3: https://docs.google.com/spreadsheets/d/1qZ7OxGjqt56luc8DZEz5g4MF8LoCQQiITOnMh7kr7BA | R3: {=INDEX('2023-07(89錯誤)'!$D:$D, MATCH(1, ('2023-07(89錯誤)'!$A:$A=A3)*('2023-07(89錯誤)'!$B:$B=B3), 0))} -> 201690 | S3: =R3-D3 -> 0
A4: 果果堅果企業社 | B4: 寄倉新約 | C4: vivi.huang | D4: 1375168 | E4: 282085 | F4: 6873 | G4: 27513 | H4: 48139 | I4: 34381 | J4: 0 | K4: 49852 | L4: 0 | M4: 7674 | N4: -2097.1 | O4: https://docs.google.com/spreadsheets/d/1k6WNFdUcdTW-ylODSWGnVD6QFQXyTZL0DQDOY5I3f9A | R4: {=INDEX('2023-07(89錯誤)'!$D:$D, MATCH(1, ('2023-07(89錯誤)'!$A:$A=A4)*('2023-07(89錯誤)'!$B:$B=B4), 0))} -> 1375168 | S4: =R4-D4 -> 0
A5: 佳格食品股份有限公司 | B5: 寄倉舊約 | C5: catherine.yeh | D5: 5756 | E5: 863 | F5: 0 | G5: 0 | H5: 0 | I5: 0 | J5: 0 | K5: 0 | L5: 0 | M5: 0 | N5: 0 | O5: https://docs.google.com/spreadsheets/d/1MiOXYXGdZol6-_z-yStCUuSSBOQ1aY_WKxJCqTe06vA | R5: {=INDEX('2023-07(89錯誤)'!$D:$D, MATCH(1, ('2023-07(89錯誤)'!$A:$A=A5)*('2023-07(89錯誤)'!$B:$B=B5), 0))} -> 12567 | S5: =R5-D5 -> 6811 | U5: =SUM(S:S) -> 959043
A6: 喬山健康科技股份有限公司東大分公司 | B6: 寄倉新約 | C6: catherine.yeh | D6: 3991 | E6: 720 | F6: 20 | G6: 81 | H6: 139 | I6: 102 | J6: 10 | K6: 402 | L6: 10 | M6: 421 | N6: -566 | O6: https://docs.google.com/spreadsheets/d/1Xwd0gkimhGz7rCATqksp0Yuy6ELblWw1Yv6KokNP8Jk | R6: {=INDEX('2023-07(89錯誤)'!$D:$D, MATCH(1, ('2023-07(89錯誤)'!$A:$A=A6)*('2023-07(89錯誤)'!$B:$B=B6), 0))} -> 11315 | S6: =R6-D6 -> 7324
A7: 明奇食品有限公司 | B7: 寄倉新約 | C7: catherine.yeh | D7: 37537 | E7: 7507 | F7: 187 | G7: 750 | H7: 1313 | I7: 939 | J7: 1280 | K7: 901 | L7: 1280 | M7: 509 | N7: 0 | O7: https://docs.google.com/spreadsheets/d/1YH4p5MPBySx9lBSJqMPDvlaPGIOpMkBblyqcbwm3xN0 | R7: {=INDEX('2023-07(89錯誤)'!$D:$D, MATCH(1, ('2023-07(89錯誤)'!$A:$A=A7)*('2023-07(89錯誤)'!$B:$B=B7), 0))} -> 37537 | S7: =R7-D7 -> 0
A8: 萬灃興貿易有限公司 | B8: 寄倉新約 | C8: catherine.yeh | D8: 37455 | E8: 7695 | F8: 185 | G8: 748 | H8: 1310 | I8: 936 | J8: 306 | K8: 1583 | L8: 306 | M8: 237 | N8: 0 | O8: https://docs.google.com/spreadsheets/d/1JSyons7JUyAqtECbpa1TWIZSyQCjHFTsfbgOMcry_OA | R8: {=INDEX('2023-07(89錯誤)'!$D:$D, MATCH(1, ('2023-07(89錯誤)'!$A:$A=A8)*('2023-07(89錯誤)'!$B:$B=B8), 0))} -> 37455 | S8: =R8-D8 -> 0
A9: 愛上大數據股份有限公司 | B9: 轉單合約 | C9: catherine.yeh | D9: 4740 | E9: 948 | F9: 0 | G9: 95 | H9: 379 | I9: 0 | J9: 0 | K9: 0 | L9: 0 | M9: 0 | N9: 0 | O9: https://docs.google.com/spreadsheets/d/1OnQ6SLJANgfBLM5_6dIRX-RWP-MTTc7sfl8lYzZiRgY | R9: {=INDEX('2023-07(89錯誤)'!$D:$D, MATCH(1, ('2023-07(89錯誤)'!$A:$A=A9)*('2023-07(89錯誤)'!$B:$B=B9), 0))} -> 4740 | S9: =R9-D9 -> 0
A10: 大誠益國際實業有限公司 | B10: 寄倉新約 | C10: catherine.yeh | D10: 52615 | E10: 10523 | F10: 263 | G10: 1052 | H10: 1841 | I10: 1315 | J10: 450 | K10: 447 | L10: 450 | M10: 86 | N10: 0 | O10: https://docs.google.com/spreadsheets/d/1uP2FYqWSRQs9idDxInBcw6iYckaO6r7i_7Ettp2-0vs | R10: {=INDEX('2023-07(89錯誤)'!$D:$D, MATCH(1, ('2023-07(89錯誤)'!$A:$A=A10)*('2023-07(89錯誤)'!$B:$B=B10), 0))} -> 52615 | S10: =R10-D10 -> 0
A11: 錸臻賦食品行 | B11: 轉單合約 | C11: catherine.yeh | D11: 6639 | E11: 1328 | F11: 0 | G11: 133 | H11: 531 | I11: 0 | J11: 0 | K11: 0 | L11: 0 | M11: 0 | N11: 0 | O11: https://docs.google.com/spreadsheets/d/1kQUcmKu2VKQEyL_H44mUlC9mG-oCNX0ydbIWGzU7lJk | R11: {=INDEX('2023-07(89錯誤)'!$D:$D, MATCH(1, ('2023-07(89錯誤)'!$A:$A=A11)*('2023-07(89錯誤)'!$B:$B=B11), 0))} -> 6639 | S11: =R11-D11 -> 0
A12: 登薾國際貿易股份有限公司 | B12: 寄倉新約 | C12: vivi.huang | D12: 7100 | E12: 1420 | F12: 36 | G12: 142 | H12: 249 | I12: 178 | J12: 13 | K12: 135 | L12: 13 | M12: 58 | N12: 0 | O12: https://docs.google.com/spreadsheets/d/1xqe0sEiqLsVU9GtxkEo2GSYHavRmNg0AAd6qOac2Z-s | R12: {=INDEX('2023-07(89錯誤)'!$D:$D, MATCH(1, ('2023-07(89錯誤)'!$A:$A=A12)*('2023-07(89錯誤)'!$B:$B=B12), 0))} -> 7100 | S12: =R12-D12 -> 0
A13: 亞帝士運動用品 | B13: 寄倉新約 | C13: 周芃葳 | D13: 1979 | E13: 396 | F13: 9 | G13: 40 | H13: 69 | I13: 49 | J13: 15 | K13: 17 | L13: 15 | M13: 55 | N13: 0 | O13: https://docs.google.com/spreadsheets/d/1qAN7o47Y8iuS_fp2yLmYqxgZwx3v_wWGITqwYqueB6Y | R13: {=INDEX('2023-07(89錯誤)'!$D:$D, MATCH(1, ('2023-07(89錯誤)'!$A:$A=A13)*('2023-07(89錯誤)'!$B:$B=B13), 0))} -> 1979 | S13: =R13-D13 -> 0
A14: 呈芳食品行 | B14: 寄倉新約 | C14: catherine.yeh | D14: 4374 | E14: 875 | F14: 22 | G14: 87 | H14: 153 | I14: 109 | J14: 135 | K14: 305 | L14: 135 | M14: 34 | N14: 0 | O14: https://docs.google.com/spreadsheets/d/1TV2-2kCWldeDp_-UT2fEWPua75KOCXt1Q7-9FT2iFro | R14: {=INDEX('2023-07(89錯誤)'!$D:$D, MATCH(1, ('2023-07(89錯誤)'!$A:$A=A14)*('2023-07(89錯誤)'!$B:$B=B14), 0))} -> 4374 | S14: =R14-D14 -> 0
A15: 寶齡富錦生技股份有限公司 | B15: 寄倉新約 | C15: vivi.huang | D15: 13476 | E15: 2695 | F15: 68 | G15: 270 | H15: 473 | I15: 338 | J15: 280 | K15: 161 | L15: 280 | M15: 51 | N15: 0 | O15: https://docs.google.com/spreadsheets/d/1odWE6A1q9sfIZWoG0rdzOwZOkJRtUQjvdOyPs7Ozkt4 | R15: {=INDEX('2023-07(89錯誤)'!$D:$D, MATCH(1, ('2023-07(89錯誤)'!$A:$A=A15)*('2023-07(89錯誤)'!$B:$B=B15), 0))} -> 13476 | S15: =R15-D15 -> 0
A16: 台灣奇亞子股份有限公司 | B16: 寄倉新約 | C16: catherine.yeh | D16: 0 | E16: 0 | F16: 0 | G16: 0 | H16: 0 | I16: 0 | J16: 0 | K16: 0 | L16: 0 | M16: 61 | N16: 0 | O16: https://docs.google.com/spreadsheets/d/19DF0ijQUbSJp6VfjRoD1Du3NYSiDJG9xrQyhFHnmgnY | R16: {=INDEX('2023-07(89錯誤)'!$D:$D, MATCH(1, ('2023-07(89錯誤)'!$A:$A=A16)*('2023-07(89錯誤)'!$B:$B=B16), 0))} -> 0 | S16: =R16-D16 -> 0
A17: 魔咕飲國際生技有限公司 | B17: 寄倉新約 | C17: catherine.yeh | D17: 0 | E17: 0 | F17: 0 | G17: 0 | H17: 0 | I17: 0 | J17: 0 | K17: 0 | L17: 0 | M17: 32 | N17: 0 | O17: https://docs.google.com/spreadsheets/d/1xPINU6eHTUEWdQ8tf8s9mca_bwWOHLkxpIjyzAgl29M | R17: {=INDEX('2023-07(89錯誤)'!$D:$D, MATCH(1, ('2023-07(89錯誤)'!$A:$A=A17)*('2023-07(89錯誤)'!$B:$B=B17), 0))} -> 0 | S17: =R17-D17 -> 0
... A73: 百鎰生物科技有限公司 | B73: 轉單合約 | C73: vivi.huang | D73: 1200 | E73: 240 | F73: 0 | G73: 24 | H73: 96 | I73: 0 | J73: 0 | K73: 0 | L73: 0 | M73: 0 | N73: 0 | O73: https://docs.google.com/spreadsheets/d/1f-icampFpQBuGkpJt31PCIPEVZse7d802bZip3_6m30 | R73: {=INDEX('2023-07(89錯誤)'!$D:$D, MATCH(1, ('2023-07(89錯誤)'!$A:$A=A73)*('2023-07(89錯誤)'!$B:$B=B73), 0))} -> 1200 | S73: =R73-D73 -> 0
A74: 偉溢國際開發有限公司 | B74: 寄倉新約 | C74: 周芃葳 | D74: 10830 | E74: 2166 | F74: 51 | G74: 220 | H74: 381 | I74: 271 | J74: 150 | K74: 544 | L74: 150 | M74: 417 | N74: 0 | O74: https://docs.google.com/spreadsheets/d/18yz1rvgsxkkGe0oCpgQOeQ827pTjlp4K65pfLZEFNr4 | R74: {=IFNA(INDEX('2023-07(89錯誤)'!$D:$D, MATCH(1, ('2023-07(89錯誤)'!$A:$A=A74)*('2023-07(89錯誤)'!$B:$B=B74), 0)),0)} -> 0 | S74: =R74-D74 -> -10830
A75: 特德寶有限公司 | B75: 寄倉新約 | C75: catherine.yeh | D75: 8070 | E75: 1648 | F75: 40 | G75: 162 | H75: 282 | I75: 201 | J75: 305 | K75: 288 | L75: 305 | M75: 463 | N75: 0 | O75: https://docs.google.com/spreadsheets/d/1W49lqodlVaGD0w1-hXiQz_Rm5O6NG7ySrJE9juIMhAQ | R75: {=INDEX('2023-07(89錯誤)'!$D:$D, MATCH(1, ('2023-07(89錯誤)'!$A:$A=A75)*('2023-07(89錯誤)'!$B:$B=B75), 0))} -> 8070 | S75: =R75-D75 -> 0
A76: 楓香林生活科技有限公司 | B76: 寄倉新約 | C76: vivi.huang | D76: 0 | E76: 0 | F76: 0 | G76: 0 | H76: 0 | I76: 0 | J76: 0 | K76: 0 | L76: 0 | M76: 17 | N76: 0 | O76: https://docs.google.com/spreadsheets/d/1Szj4arZTMUfG0dHdnyal0_C8i1Y9LnO190ObPNebruI | R76: {=INDEX('2023-07(89錯誤)'!$D:$D, MATCH(1, ('2023-07(89錯誤)'!$A:$A=A76)*('2023-07(89錯誤)'!$B:$B=B76), 0))} -> 0 | S76: =R76-D76 -> 0
A77: 寰宇生物科技股份有限公司 | B77: 寄倉新約 | C77: vivi.huang | D77: 48071 | E77: 9589 | F77: 241 | G77: 963 | H77: 1683 | I77: 1202 | J77: 1720 | K77: 693 | L77: 1720 | M77: 144 | N77: 0 | O77: https://docs.google.com/spreadsheets/d/1vFfiBLRuhv81f9gUhgzFxxXc9GNPP7LNet_EUFKTMkw | R77: {=INDEX('2023-07(89錯誤)'!$D:$D, MATCH(1, ('2023-07(89錯誤)'!$A:$A=A77)*('2023-07(89錯誤)'!$B:$B=B77), 0))} -> 48071 | S77: =R77-D77 -> 0
A78: 嘉優生技股份有限公司 | B78: 寄倉新約 | C78: vivi.huang | D78: 0 | E78: 0 | F78: 0 | G78: 0 | H78: 0 | I78: 0 | J78: 0 | K78: 0 | L78: 0 | M78: 38 | N78: 0 | O78: https://docs.google.com/spreadsheets/d/1nBSF-8TKYib8iCeoi46P515ZPAnDWX_Kes0qMxy0XQU | R78: {=INDEX('2023-07(89錯誤)'!$D:$D, MATCH(1, ('2023-07(89錯誤)'!$A:$A=A78)*('2023-07(89錯誤)'!$B:$B=B78), 0))} -> 0 | S78: =R78-D78 -> 0
A79: 新三觀股份有限公司 | B79: 寄倉新約 | C79: vivi.huang | D79: 0 | E79: 0 | F79: 0 | G79: 0 | H79: 0 | I79: 0 | J79: 0 | K79: 0 | L79: 0 | M79: 32 | N79: 0 | O79: https://docs.google.com/spreadsheets/d/1doOEyOvIUGzYhB17q68xTmvyrNZg-CzNPfiNPNM4nkM | R79: {=INDEX('2023-07(89錯誤)'!$D:$D, MATCH(1, ('2023-07(89錯誤)'!$A:$A=A79)*('2023-07(89錯誤)'!$B:$B=B79), 0))} -> 0 | S79: =R79-D79 -> 0
A80: 中樞生技股份有限公司 | B80: 寄倉新約 | C80: vivi.huang | D80: 0 | E80: 0 | F80: 0 | G80: 0 | H80: 0 | I80: 0 | J80: 0 | K80: 0 | L80: 0 | M80: 3 | N80: 0 | O80: https://docs.google.com/spreadsheets/d/1xZ6cwRqCvVavQqTxbojGtRM1ySB9MRyt_591pRvW5oM | R80: {=INDEX('2023-07(89錯誤)'!$D:$D, MATCH(1, ('2023-07(89錯誤)'!$A:$A=A80)*('2023-07(89錯誤)'!$B:$B=B80), 0))} -> 0 | S80: =R80-D80 -> 0
A81: 大數行銷有限公司 | B81: 寄倉新約 | C81: vivi.huang | D81: 1080 | E81: 216 | F81: 5 | G81: 22 | H81: 38 | I81: 27 | J81: 10 | K81: 11 | L81: 10 | M81: 34 | N81: 0 | O81: https://docs.google.com/spreadsheets/d/17etuuBmFyk4igcUQsAEm2c6TRJBGytnDes9l3uVFDP8 | R81: {=INDEX('2023-07(89錯誤)'!$D:$D, MATCH(1, ('2023-07(89錯誤)'!$A:$A=A81)*('2023-07(89錯誤)'!$B:$B=B81), 0))} -> 1080 | S81: =R81-D81 -> 0
A82: 家酪優企業有限公司 | B82: 寄倉新約 | C82: vivi.huang | D82: 31192 | E82: 7174 | F82: 156 | G82: 624 | H82: 1092 | I82: 780 | J82: 680 | K82: 325 | L82: 680 | M82: 20 | N82: -16992 | O82: https://docs.google.com/spreadsheets/d/1aBe5xue8b21fXVFZtDXRRdO0Ot28bHkR5hlSmgOWy-M | R82: {=INDEX('2023-07(89錯誤)'!$D:$D, MATCH(1, ('2023-07(89錯誤)'!$A:$A=A82)*('2023-07(89錯誤)'!$B:$B=B82), 0))} -> 31192 | S82: =R82-D82 -> 0
A83: 寶瓏股份有限公司 | B83: 寄倉新約 | C83: vivi.huang | D83: 0 | E83: 0 | F83: 0 | G83: 0 | H83: 0 | I83: 0 | J83: 0 | K83: 0 | L83: 0 | M83: 15 | N83: 0 | O83: https://docs.google.com/spreadsheets/d/1o3T0Vmk1yswpjEVgAS2fjrrFtYGJs_d6cbqysHJm37s | R83: {=INDEX('2023-07(89錯誤)'!$D:$D, MATCH(1, ('2023-07(89錯誤)'!$A:$A=A83)*('2023-07(89錯誤)'!$B:$B=B83), 0))} -> 0 | S83: =R83-D83 -> 0
A84: 淳媞國際股份有限公司 | B84: 寄倉新約 | C84: vivi.huang | D84: 0 | E84: 0 | F84: 0 | G84: 0 | H84: 0 | I84: 0 | J84: 0 | K84: 0 | L84: 0 | M84: 21 | N84: 0 | O84: https://docs.google.com/spreadsheets/d/1idNzz3FWbjJMGKBXdx9MeN-_HHiXFrADIu49H6zNgB0 | R84: {=INDEX('2023-07(89錯誤)'!$D:$D, MATCH(1, ('2023-07(89錯誤)'!$A:$A=A84)*('2023-07(89錯誤)'!$B:$B=B84), 0))} -> 0 | S84: =R84-D84 -> 0
A85: 皮諾喬有限公司 | B85: 寄倉新約 | C85: catherine.yeh | D85: 1410 | E85: 282 | F85: 8 | G85: 28 | H85: 49 | I85: 35 | J85: 4 | K85: 69 | L85: 4 | M85: 169 | N85: 0 | O85: https://docs.google.com/spreadsheets/d/1fFQN_XTA55Yh8OjDi8pfiCt-ANMhh1H_ptpTdnCm-wY | R85: {=INDEX('2023-07(89錯誤)'!$D:$D, MATCH(1, ('2023-07(89錯誤)'!$A:$A=A85)*('2023-07(89錯誤)'!$B:$B=B85), 0))} -> 1410 | S85: =R85-D85 -> 0
A86: 精緻生活企業有限公司 | B86: 寄倉新約 | C86: vivi.huang | D86: 0 | E86: 0 | F86: 0 | G86: 0 | H86: 0 | I86: 0 | J86: 0 | K86: 0 | L86: 0 | M86: 8 | N86: 0 | O86: https://docs.google.com/spreadsheets/d/1v0VPGA985QnvjRzFBHyjMViEH114wz0RTZ4yZaZFIas | R86: {=INDEX('2023-07(89錯誤)'!$D:$D, MATCH(1, ('2023-07(89錯誤)'!$A:$A=A86)*('2023-07(89錯誤)'!$B:$B=B86), 0))} -> 0 | S86: =R86-D86 -> 0
... A212: 旭盛智慧科技有限公司 | B212: 轉單合約 | C212: catherine.yeh | D212: 1497 | E212: 449 | F212: 0 | G212: 30 | H212: 120 | I212: 0 | J212: 0 | K212: 0 | L212: 0 | M212: 0 | N212: 0 | O212: https://docs.google.com/spreadsheets/d/1t8TnMhkAzS5GkWn5GfXHQ-srsj4V4Y8uxw1Ry5QNn6o | R212: {=INDEX('2023-07(89錯誤)'!$D:$D, MATCH(1, ('2023-07(89錯誤)'!$A:$A=A212)*('2023-07(89錯誤)'!$B:$B=B212), 0))} -> 1497 | S212: =R212-D212 -> 0
A213: 艾斯德有限公司 | B213: 寄倉新約 | C213: vivi.huang | D213: 0 | E213: 0 | F213: 0 | G213: 0 | H213: 0 | I213: 0 | J213: 0 | K213: 0 | L213: 0 | M213: 1 | N213: 0 | O213: https://docs.google.com/spreadsheets/d/1F8nDB5zl4-ZpggidCkAlNWIouY59L8niXX9wH6IRsaM | R213: {=IFNA(INDEX('2023-07(89錯誤)'!$D:$D, MATCH(1, ('2023-07(89錯誤)'!$A:$A=A213)*('2023-07(89錯誤)'!$B:$B=B213), 0)),0)} -> 0 | S213: =R213-D213 -> 0
R214: {=INDEX('2023-07(89錯誤)'!$D:$D, MATCH(1, ('2023-07(89錯誤)'!$A:$A=A214)*('2023-07(89錯誤)'!$B:$B=B214), 0))}

Sheet 2023-08
A1: 廠商名稱 | B1: 合作模式 | C1: 負責人 | D1: 銷售總額 | E1: 抽成 | F1: 平台維護費 | G1: 金流處理費 | H1: 行銷推廣費 | I1: 活動贊助費 | J1: 運費攤提 | K1: 人工處理費 | L1: 倉租加總 | M1: 吸收額 | N1: 報表連結
A2: 果果堅果企業社 | B2: 寄倉新約 | C2: vivi.huang | D2: 1814397 | E2: 375550 | F2: 9070 | G2: 36303 | H2: 63507 | I2: 45367 | J2: 71701 | K2: 0 | L2: 10111 | M2: 300 | N2: https://docs.google.com/spreadsheets/d/1Ec_-XPZ4xh9ve7E_6C16pmKlbdUpaJwFm1S7uMVXPdI
A3: 樂維根有限公司 | B3: 寄倉新約 | C3: vivi.huang | D3: 894858 | E3: 205817 | F3: 4478 | G3: 17902 | H3: 31320 | I3: 22375 | J3: 39384 | K3: 210 | L3: 4571 | M3: 0 | N3: https://docs.google.com/spreadsheets/d/1EV8OQcJZCCo9TC0mxVBBAHbY1uQs_e4TZJRz04fQo2g
A4: 健生活股份有限公司 | B4: 寄倉新約 | C4: vivi.huang | D4: 454672 | E4: 90934 | F4: 2272 | G4: 9093 | H4: 15916 | I4: 11372 | J4: 9091 | K4: 4180 | L4: 2156 | M4: 7181 | N4: https://docs.google.com/spreadsheets/d/1uXX7Z_YeEiae01mWJlmiyiGHJzt7A9sAV0pYzvPsb_8
A5: 禹函有限公司 | B5: 轉單合約 | C5: ting.lin | D5: 400743 | E5: 60108 | F5: 0 | G5: 8014 | H5: 32061 | I5: 0 | J5: 0 | K5: 0 | L5: 0 | M5: 0 | N5: https://docs.google.com/spreadsheets/d/1FuTOjHTMYfgFbc0xvH3pSQcRYt3L48SguGEdHU0aneA
A6: 森宏生技股份有限公司 | B6: 寄倉新約 | C6: vivi.huang | D6: 336841 | E6: 64130 | F6: 1687 | G6: 6739 | H6: 11795 | I6: 8429 | J6: 6158 | K6: 7185 | L6: 450 | M6: 0 | N6: https://docs.google.com/spreadsheets/d/1B2P-zsRd1MqIfdYS3VxdDz_vHFTJVtxDfAzyF-tpYZ0
A7: 青荷國際有限公司 | B7: 寄倉新約 | C7: catherine.yeh | D7: 251611 | E7: 47732 | F7: 1260 | G7: 5033 | H7: 8804 | I7: 6294 | J7: 12565 | K7: 7655 | L7: 653 | M7: 0 | N7: https://docs.google.com/spreadsheets/d/14TmXNitxGNkuH7MnMXhk2Hkah_COFztS_Os-R-bS85A
A8: 柏立奧有限公司 | B8: 寄倉新約 | C8: vivi.huang | D8: 206475 | E8: 44118 | F8: 1037 | G8: 4133 | H8: 7236 | I8: 5170 | J8: 5640 | K8: 3939 | L8: 945 | M8: -300 | N8: https://docs.google.com/spreadsheets/d/17wPn6BsAcdTvHuodLYK3Y0Xyaf1aVLEfXny_57Ef6qY
A9: 鑫欣羿股份有限公司 | B9: 寄倉新約 | C9: catherine.yeh | D9: 155980 | E9: 35876 | F9: 780 | G9: 3119 | H9: 5460 | I9: 3901 | J9: 1880 | K9: 0 | L9: 528 | M9: 0 | N9: https://docs.google.com/spreadsheets/d/1N8DB0KTS1vdY40QAwq1XMSCVhSpNfbNznNz0tBuk8d0
A10: 奕瑪國際行銷股份有限公司 | B10: 寄倉新約 | C10: vivi.huang | D10: 125302 | E10: 25060 | F10: 626 | G10: 2507 | H10: 4387 | I10: 3133 | J10: 4266 | K10: 848 | L10: 920 | M10: 0 | N10: https://docs.google.com/spreadsheets/d/1O0v-NVxYdwD4bK8G0rYc0YBjE7W4aJMkB-QIHOClgBg
A11: 台灣恩斯艾國際有限公司 | B11: 寄倉新約 | C11: vivi.huang | D11: 121648 | E11: 28800 | F11: 606 | G11: 2435 | H11: 4258 | I11: 3042 | J11: 1588 | K11: 1620 | L11: 57 | M11: 0 | N11: https://docs.google.com/spreadsheets/d/1oGfpo4q62BLJT5mj1kL87Q5YofKLVJ1_g4IrrpQnmpA
A12: 大誠益國際實業有限公司 | B12: 寄倉新約 | C12: catherine.yeh | D12: 107610 | E12: 21522 | F12: 538 | G12: 2152 | H12: 3767 | I12: 2690 | J12: 960 | K12: 985 | L12: 27 | M12: 50 | N12: https://docs.google.com/spreadsheets/d/1trmjtWItgzkthq5G6HjElseYOl_w0e3nlpI483bmy7E
A13: 廣紘國際股份有限公司 | B13: 寄倉新約 | C13: catherine.yeh | D13: 107379 | E13: 21525 | F13: 534 | G13: 2148 | H13: 3760 | I13: 2685 | J13: 6730 | K13: 0 | L13: 431 | M13: 0 | N13: https://docs.google.com/spreadsheets/d/1iVSycRYyk2L8YJB1ZyfZ6B1VuAA7L-jGOKNXIOVJMnE
... A188: 有熊運動股份有限公司 | B188: 轉單合約 | C188: vivi.huang | D188: 0 | E188: 0 | F188: 0 | G188: 0 | H188: 0 | I188: 0 | J188: 0 | K188: 0 | L188: 0 | M188: 448 | N188: https://docs.google.com/spreadsheets/d/1pHBXBZSu9Dcr-CBeH9upc-1ptYfLi5hc7qroEpTatXQ

Sheet 2023-09
A1: 廠商名稱 | B1: 合作模式 | C1: 負責人 | D1: 銷售總額 | E1: 抽成 | F1: 平台維護費 | G1: 金流處理費 | H1: 行銷推廣費 | I1: 活動贊助費 | J1: 運費攤提 | K1: 人工處理費 | L1: 倉租加總 | M1: 吸收額 | N1: 報表連結
A2: 明奇食品有限公司 | B2: 寄倉新約 | C2: duncan.lin | D2: 35905 | E2: 7181 | F2: 174 | G2: 732 | H2: 1261 | I2: 913 | J2: 1845 | K2: 1236 | L2: 236 | M2: 0 | N2: https://docs.google.com/spreadsheets/d/1WjGjUmgWpQNUg6nb1uvcgRLyKNUBRdQn3VjABg2v77M
A3: 萬灃興貿易有限公司 | B3: 寄倉新約 | C3: duncan.lin | D3: 34645 | E3: 6929 | F3: 184 | G3: 684 | H3: 1208 | I3: 852 | J3: 2275 | K3: 220 | L3: 107 | M3: 0 | N3: https://docs.google.com/spreadsheets/d/1jBhQV_qZN14YZM4-KIX3127pCRTVUv-CMJtSLvvGnUg
A4: 愛上大數據股份有限公司 | B4: 轉單合約 | C4: duncan.lin | D4: 2370 | E4: 474 | F4: 0 | G4: 47 | H4: 190 | I4: 0 | J4: 0 | K4: 0 | L4: 0 | M4: 0 | N4: https://docs.google.com/spreadsheets/d/1b54E1EOMjYGLjvwHeZ8_3jTr-ugIPT1gu72VIAIGhMU
A5: 大誠益國際實業有限公司 | B5: 寄倉新約 | C5: duncan.lin | D5: 76435 | E5: 15287 | F5: 382 | G5: 1529 | H5: 2675 | I5: 1911 | J5: 709 | K5: 645 | L5: 36 | M5: 0 | N5: https://docs.google.com/spreadsheets/d/1ozN27AHptLP5VHxW_iv0L3lPFwsWvejdlsbRqNFlvMY
A6: 錸臻賦食品行 | B6: 轉單合約 | C6: duncan.lin | D6: 2821 | E6: 564 | F6: 0 | G6: 56 | H6: 226 | I6: 0 | J6: 0 | K6: 0 | L6: 0 | M6: 0 | N6: https://docs.google.com/spreadsheets/d/12dsNFvlxXXwY0RJbkH0HQPAn8CtIdU3E69_2OYCZnYU
A7: 登薾國際貿易股份有限公司 | B7: 寄倉新約 | C7: vivi.huang | D7: 9100 | E7: 1820 | F7: 47 | G7: 182 | H7: 320 | I7: 229 | J7: 77 | K7: 18 | L7: 36 | M7: 0 | N7: https://docs.google.com/spreadsheets/d/1MNJS3klZtOyaN31SOEK5nNjBA5GmfSN6_Jf57M9Nugw
A8: 老妹的灶下有限公司 | B8: 轉單合約 | C8: duncan.lin | D8: 1250 | E8: 250 | F8: 0 | G8: 25 | H8: 100 | I8: 0 | J8: 0 | K8: 0 | L8: 0 | M8: 0 | N8: https://docs.google.com/spreadsheets/d/1Jw4jeLhCdSPdtlYrPeP7eQRYkf0_p6Wift7-68r49wA
A9: 亞帝士運動用品 | B9: 寄倉新約 | C9: 周芃葳 | D9: 0 | E9: 0 | F9: 0 | G9: 0 | H9: 0 | I9: 0 | J9: 0 | K9: 0 | L9: 55 | M9: 0 | N9: https://docs.google.com/spreadsheets/d/1NL1ZBiIJAS9h2P_TyUotsa6sr9RUfbA6F4V_TRR65XE
A10: 呈芳食品行 | B10: 寄倉新約 | C10: duncan.lin | D10: 4050 | E10: 810 | F10: 23 | G10: 77 | H10: 144 | I10: 100 | J10: 537 | K10: 125 | L10: 52 | M10: 0 | N10: https://docs.google.com/spreadsheets/d/1M8CKfZjEI8CdiSDElE-5VrNFblAVhKIZdUishKxogsM
A11: 寶齡富錦生技股份有限公司 | B11: 寄倉新約 | C11: vivi.huang | D11: 48346 | E11: 12285 | F11: 242 | G11: 968 | H11: 1693 | I11: 1209 | J11: 354 | K11: 980 | L11: 34 | M11: 0 | N11: https://docs.google.com/spreadsheets/d/1b1NSagfEyNixRN9hlaiTQuZfXsUhXudGKyB7KPz7axk
A12: 鑫欣羿股份有限公司 | B12: 寄倉新約 | C12: duncan.lin | D12: 120978 | E12: 27825 | F12: 620 | G12: 2423 | H12: 4222 | I12: 3027 | J12: 7062 | K12: 0 | L12: 545 | M12: 0 | N12: https://docs.google.com/spreadsheets/d/12XOw59E_tV1MSDEu61ehxWdF4MUc0Xs0QBm8XIvqO38
A13: 柏立奧有限公司 | B13: 寄倉新約 | C13: vivi.huang | D13: 143735 | E13: 30640 | F13: 671 | G13: 2909 | H13: 5074 | I13: 3580 | J13: 4872 | K13: 2596 | L13: 1014 | M13: 0 | N13: https://docs.google.com/spreadsheets/d/1TQX31m_TStCYR-k3bYzlIzt5ZQe-SaFyE5Jc1P8cFnI
... A169: 仁平有限公司 | B169: 寄倉新約 | C169: james.tseng | D169: 10889 | E169: 2831 | F169: 54 | G169: 218 | H169: 381 | I169: 272 | J169: 423 | K169: 250 | L169: 21 | M169: 0 | N169: https://docs.google.com/spreadsheets/d/17Bu-xCnsKvlEETUkPXSsK5AEn_SSf1GD4yH2uVXdq1c
A170: 盛禾生醫國際事業有限公司 | B170: 轉單合約 | C170: shelly.hsieh | D170: 5610 | E170: 1412 | F170: 0 | G170: 112 | H170: 449 | J170: 0 | K170: 0 | L170: 0 | M170: 0 | N170: https://docs.google.com/spreadsheets/d/13OmX7leJj-eHGaBhurWw8MPeDTWEOZVWC23Y9aZ72_s
A171: 統盛國際股份有限公司 | B171: 轉單合約 | C171: duncan.lin | D171: 9192 | E171: 2114 | F171: 0 | G171: 184 | H171: 735 | I171: 0 | J171: 0 | K171: 0 | L171: 0 | M171: 0 | N171: https://docs.google.com/spreadsheets/d/18AUskMMi2rozlcIXEqxsVIbwU-CfNj0C8FbvmfNHUPw
A172: 松誠雜糧企業社 | B172: 轉單合約 | C172: duncan.lin | D172: 8865 | E172: 0 | F172: 0 | G172: 0 | H172: 0 | I172: 0 | J172: 0 | K172: 0 | L172: 0 | M172: 0 | N172: https://docs.google.com/spreadsheets/d/1rIxZFZYJIW6dcFCc2lYAGGEvnq3lS2Y4N_EucKJRvCk
A173: 大漢酵素生物科技股份有限公司 | B173: 轉單合約 | C173: 白乙君 | D173: 4354 | E173: 0 | F173: 0 | G173: 0 | H173: 0 | I173: 0 | J173: 0 | K173: 0 | L173: 0 | M173: 0 | N173: https://docs.google.com/spreadsheets/d/1fEFOJa6VQicGzkRQRW_pHlXENAZYL56zkRgQsRvyGHg
A174: 山祿國際有限公司 | B174: 轉單合約 | C174: ashley.lin | D174: 7110 | E174: 1635 | F174: 0 | G174: 142 | H174: 569 | I174: 0 | J174: 0 | K174: 0 | L174: 0 | M174: 0 | N174: https://docs.google.com/spreadsheets/d/1drz3X0iNgLHm9vrHtkcvsZ4DQpVx_4XgydPsG-iwSas
A175: 焠爾瑯股份有限公司 | B175: 轉單合約 | C175: shelly.hsieh | D175: 4676 | E175: 1146 | F175: 0 | G175: 94 | H175: 374 | I175: 0 | J175: 0 | K175: 0 | L175: 0 | M175: 0 | N175: https://docs.google.com/spreadsheets/d/1bJfo0ftazPSX9N-pBAa84gtY_v006HFKPTG6kN03WM8
A176: 毅誠商貿有限公司 | B176: 寄倉新約 | C176: duncan.lin | D176: 2781 | E176: 616 | F176: 14 | G176: 56 | H176: 98 | I176: 70 | J176: 120 | K176: 0 | L176: 27 | M176: 0 | N176: https://docs.google.com/spreadsheets/d/1Ym66xqkycx2yMyihq5kYSKxhT3SeGaqjTltgiF8Ej5M
A177: 春霖國際股份有限公司 | B177: 轉單合約 | C177: duncan.lin | D177: 4301 | E177: 1075 | F177: 0 | G177: 86 | H177: 344 | I177: 0 | J177: 0 | K177: 0 | L177: 0 | M177: 0 | N177: https://docs.google.com/spreadsheets/d/1RfvR2Gp7Oski9F-kTsokU04CWoAxOb-4YBThqjYq0uQ
A178: 芮斯特有限公司 | B178: 寄倉新約 | C178: james.tseng | D178: 76670 | E178: 17634 | F178: 384 | G178: 1533 | H178: 2686 | I178: 1918 | J178: 4027 | K178: 664 | L178: 228 | M178: 0 | N178: https://docs.google.com/spreadsheets/d/1tmtNIwOCVfPdxEiZk6nmTLmh5bhpHKLaj22aSVpbldc
A179: 元鼎璞真股份有限公司 | B179: 轉單合約 | C179: james.tseng | D179: 2100 | E179: 525 | F179: 0 | G179: 42 | H179: 168 | I179: 0 | J179: 0 | K179: 0 | L179: 0 | M179: 0 | N179: https://docs.google.com/spreadsheets/d/1-WBN7E0Duh6bhUJEWLsl8ME8oPGCk_gm_o5ARGal9nc
A180: 合英勝國際有限公司 | B180: 寄倉新約 | C180: james.tseng | D180: 5394 | E180: 1241 | F180: 26 | G180: 108 | H180: 188 | I180: 134 | J180: 170 | K180: 60 | L180: 17 | M180: 0 | N180: https://docs.google.com/spreadsheets/d/1_6nh0hSfjrtVRBtdtJs-_GZTpJvWUq6lroo3cDt_dd8
A181: 昂萃生技股份有限公司 | B181: 轉單合約 | C181: shelly.hsieh | D181: 3049 | E181: 793 | F181: 0 | G181: 61 | H181: 244 | I181: 0 | J181: 0 | K181: 0 | L181: 0 | M181: 0 | N181: https://docs.google.com/spreadsheets/d/1OTPw6MVILxWj_E8QhF-XTRoRpXwXAVf10NO8_ut9rVo
A182: 綠富有限公司 | B182: 寄倉新約 | C182: james.tseng | D182: 620736 | E182: 144106 | F182: 3113 | G182: 12413 | H182: 21739 | I182: 15539 | J182: 15838 | K182: 9594 | L182: 1352 | M182: 0 | N182: https://docs.google.com/spreadsheets/d/1xmDNCbcreIbb0r4Wifw3kwlEa03GO5BegvBx-H6wwjo
... A185: 好健康國際有限公司 | B185: 寄倉新約 | C185: duncan.lin | D185: 0 | E185: 0 | F185: 0 | G185: 0 | H185: 0 | I185: 0 | J185: 0 | K185: 0 | L185: 0 | M185: 1376 | N185: https://docs.google.com/spreadsheets/d/1179TVBdC5qIHfiOxdqis5pka9_e3NMctr9ghsvGSL5k

Sheet 2023-10
A1: 廠商名稱 | B1: 合作模式 | C1: 負責人 | D1: 銷售總額 | E1: 抽成 | F1: 平台維護費 | G1: 金流處理費 | H1: 行銷推廣費 | I1: 活動贊助費 | J1: 運費攤提 | K1: 人工處理費 | L1: 倉租加總 | M1: 吸收額 | N1: 報表連結
A2: 明奇食品有限公司 | B2: 寄倉新約 | C2: duncan.lin | D2: 33671 | E2: 6734 | F2: 167 | G2: 686 | H2: 1191 | I2: 1191 | J2: 1620 | K2: 1108 | L2: 222 | M2: 0 | N2: https://docs.google.com/spreadsheets/d/1vt6UnlvrmeC_8wX4M-3nj0C6MJjBFli18bFZMkSMMfw
A3: 萬灃興貿易有限公司 | B3: 寄倉新約 | C3: duncan.lin | D3: 9881 | E3: 2105 | F3: 50 | G3: 199 | H3: 350 | I3: 350 | J3: 573 | K3: 58 | L3: 25 | M3: 17687 | N3: https://docs.google.com/spreadsheets/d/1zXkYQW-Y_P2bRxaCZpPMxJjCDpmbJHR5e9JddqiB5Us
A4: 愛上大數據股份有限公司 | B4: 轉單合約 | C4: duncan.lin | D4: 7110 | E4: 1422 | F4: 0 | G4: 142 | H4: 569 | I4: 0 | J4: 0 | K4: 0 | L4: 0 | M4: 0 | N4: https://docs.google.com/spreadsheets/d/1mZufBNa1N4zWDp184KLjA5N302ZIHGcTANUOoB3EdpY
A5: 大誠益國際實業有限公司 | B5: 寄倉新約 | C5: duncan.lin | D5: 66550 | E5: 13310 | F5: 335 | G5: 1335 | H5: 2334 | I5: 2334 | J5: 1906 | K5: 575 | L5: 63 | M5: 0 | N5: https://docs.google.com/spreadsheets/d/1LiTraVCqkvOF-Wp5gNsM1OAGLqfO3eJkaCwR8z3ISoI
A6: 登薾國際貿易股份有限公司 | B6: 寄倉新約 | C6: vivi.huang | D6: 6650 | E6: 1330 | F6: 35 | G6: 133 | H6: 236 | I6: 236 | J6: 290 | K6: 14 | L6: 44 | M6: 0 | N6: https://docs.google.com/spreadsheets/d/1SrVZ-YUrM_Dni6IcKNT7PxoQbKV4n3pAWqfwVWJtFZo
A7: 老妹的灶下有限公司 | B7: 轉單合約 | C7: duncan.lin | D7: 1949 | E7: 390 | F7: 0 | G7: 39 | H7: 156 | I7: 0 | J7: 0 | K7: 0 | L7: 0 | M7: 0 | N7: https://docs.google.com/spreadsheets/d/1QF9ZnNKTGHEYZyNa9qkwtXw5UR6iAWIOtMG-4GB04Ew
A8: 亞帝士運動用品 | B8: 寄倉新約 | C8: 周芃葳 | D8: 4260 | E8: 852 | F8: 20 | G8: 87 | H8: 150 | I8: 150 | J8: 53 | K8: 50 | L8: 57 | M8: 0 | N8: https://docs.google.com/spreadsheets/d/14PCGM3WAIXrSb0ThLQz1icVwHS0Eyau9zNYsmf5oZ6I
A9: 呈芳食品行 | B9: 寄倉新約 | C9: duncan.lin | D9: 6642 | E9: 1328 | F9: 38 | G9: 126 | H9: 240 | I9: 240 | J9: 750 | K9: 205 | L9: 70 | M9: 0 | N9: https://docs.google.com/spreadsheets/d/1JNOLH2NXiv8DeY36uWVgX6DIMPSIYMirhTzvOVcQY3g
A10: 寶齡富錦生技股份有限公司 | B10: 寄倉新約 | C10: vivi.huang | D10: 32672 | E10: 8495 | F10: 163 | G10: 657 | H10: 1144 | I10: 1129 | J10: 810 | K10: 580 | L10: 44 | M10: 0 | N10: https://docs.google.com/spreadsheets/d/1e_tstXRpyy73z7vV-Am9HYJUW2QawvwdF97UQpt9Dko
A11: 鑫欣羿股份有限公司 | B11: 寄倉新約 | C11: duncan.lin | D11: 90068 | E11: 20716 | F11: 458 | G11: 1806 | H11: 3142 | I11: 3133 | J11: 5420 | K11: 0 | L11: 1097 | M11: 0 | N11: https://docs.google.com/spreadsheets/d/1CTEe0aKyTy7rw_glITkMnM1pT8xqjlX6eBfikSAtqJs
A12: 柏立奧有限公司 | B12: 寄倉新約 | C12: vivi.huang | D12: 151688 | E12: 32708 | F12: 721 | G12: 3068 | H12: 5368 | I12: 5330 | J12: 5081 | K12: 2855 | L12: 1053 | M12: 0 | N12: https://docs.google.com/spreadsheets/d/11HwqJr1ko9rcA8ZaLX2-ixy7EvCBn7NAn1s9nu4HWSc
A13: 艾斯德有限公司 | B13: 寄倉新約 | C13: vivi.huang | D13: 0 | E13: 0 | F13: 0 | G13: 0 | H13: 0 | I13: 0 | J13: 0 | K13: 0 | L13: 16 | M13: 0 | N13: https://docs.google.com/spreadsheets/d/1fp0DK3AhfwL1z-J9qCxfcVh3zxsrH4mt0h9MoXQUVOU
... A179: 睿鼎行銷股份有限公司 | B179: 轉單合約 | C179: duncan.lin | D179: 750 | E179: 150 | F179: 0 | G179: 15 | H179: 60 | I179: 0 | J179: 0 | K179: 0 | L179: 0 | M179: 0 | N179: https://docs.google.com/spreadsheets/d/1ykgLwR4qzSrtfSbMM8zNS4K92kIdaO0eDSav72FvOpQ

Sheet 2023-11
A1: 廠商名稱 | B1: 合作模式 | C1: 負責人 | D1: 銷售總額 | E1: 抽成 | F1: 平台維護費 | G1: 金流處理費 | H1: 行銷推廣費 | I1: 活動贊助費 | J1: 運費攤提 | K1: 人工處理費 | L1: 倉租加總 | M1: 吸收額 | N1: 報表連結
A2: 艾斯德有限公司 | B2: 寄倉新約 | C2: vivi.huang | D2: 0 | E2: 0 | F2: 0 | G2: 0 | H2: 0 | I2: 0 | J2: 0 | K2: 0 | L2: 15 | M2: 0 | N2: https://docs.google.com/spreadsheets/d/1AM9g0ds9PH-wjO11q2rcz52vbzZNUk1GEjnm8YIX7V0
A3: 睿森實業有限公司 | B3: 寄倉新約 | C3: duncan.lin | D3: 0 | E3: 0 | F3: 0 | G3: 0 | H3: 0 | I3: 0 | J3: 0 | K3: 0 | L3: 2 | M3: 64 | N3: https://docs.google.com/spreadsheets/d/1JitLHb45jKFLF49H4DimyHj4VPr03RGg_8D5TU89u00
A4: 締盟股份有限公司 | B4: 寄倉新約 | C4: duncan.lin | D4: 0 | E4: 0 | F4: 0 | G4: 0 | H4: 0 | I4: 0 | J4: 0 | K4: 0 | L4: 8 | M4: 0 | N4: https://docs.google.com/spreadsheets/d/1x_btYzob4TacvjreWeoeqHVwVfgKq3DqhRsEw76lcD0
A5: 陳易國際有限公司 | B5: 寄倉新約 | C5: vivi.huang | D5: 0 | E5: 0 | F5: 0 | G5: 0 | H5: 0 | I5: 0 | J5: 0 | K5: 0 | L5: 2 | M5: 0 | N5: https://docs.google.com/spreadsheets/d/12QqLFAXrl9rsSmj2VmLv4sGYMSK4_ewz7ZHl08iyoG8
A6: 普羅客託國際開發有限公司 | B6: 寄倉新約 | C6: 張雅雯 | D6: 0 | E6: 0 | F6: 0 | G6: 0 | H6: 0 | I6: 0 | J6: 0 | K6: 0 | L6: 138 | M6: 0 | N6: https://docs.google.com/spreadsheets/d/1EHq9fk1qGCxMKgkR1o6SMwuDZqn_GUbgqdJl6fx7dOo
A7: 樂乙有限公司 | B7: 寄倉新約 | C7: vivi.huang | D7: 0 | E7: 0 | F7: 0 | G7: 0 | H7: 0 | I7: 0 | J7: 0 | K7: 0 | L7: 46 | M7: 0 | N7: https://docs.google.com/spreadsheets/d/1es7WA1Abuq_pNV1vRugP2Aa__-EWI_IiS1BO4HN5m8k
A8: 麥思有限公司 | B8: 寄倉新約 | C8: shelly.hsieh | D8: 0 | E8: 0 | F8: 0 | G8: 0 | H8: 0 | I8: 0 | J8: 0 | K8: 0 | L8: 19 | M8: 0 | N8: https://docs.google.com/spreadsheets/d/1GOF0uNwwIS472zSGp8RmQfpYYTRvNxX43_IeNNmZjQ4
A9: 楓香林生活科技有限公司 | B9: 寄倉新約 | C9: vivi.huang | D9: 0 | E9: 0 | F9: 0 | G9: 0 | H9: 0 | I9: 0 | J9: 0 | K9: 0 | L9: 3 | M9: 0 | N9: https://docs.google.com/spreadsheets/d/1SYc0CgekxESYLxGA7OMYVtHqC_qkX9uV0koaxKx4O9M
A10: 嘉優生技股份有限公司 | B10: 寄倉新約 | C10: vivi.huang | D10: 0 | E10: 0 | F10: 0 | G10: 0 | H10: 0 | I10: 0 | J10: 0 | K10: 0 | L10: 1 | M10: 0 | N10: https://docs.google.com/spreadsheets/d/11tR6EDj5lWjlsB9T3qkA2xtfPIvvDoGRlqZ4WkwG3h4
A11: 大數行銷有限公司 | B11: 寄倉新約 | C11: vivi.huang | D11: 0 | E11: 0 | F11: 0 | G11: 0 | H11: 0 | I11: 0 | J11: 0 | K11: 0 | L11: 3 | M11: 0 | N11: https://docs.google.com/spreadsheets/d/1E7wwhIzmRNRBjahDAGu5HG3d4JJaDQgSJuqsgjHb_hE
A12: 豐騰貿易有限公司 | B12: 寄倉新約 | C12: vivi.huang | D12: 0 | E12: 0 | F12: 0 | G12: 0 | H12: 0 | I12: 0 | J12: 0 | K12: 0 | L12: 5 | M12: 0 | N12: https://docs.google.com/spreadsheets/d/1_1h9l9qH0lmRR7X27Wvps-AaFFV9hDn_i5jN1tJyCzo
A13: 衣格服飾股份有限公司 | B13: 寄倉新約 | C13: 周芃葳 | D13: 0 | E13: 0 | F13: 0 | G13: 0 | H13: 0 | I13: 0 | J13: 0 | K13: 0 | L13: 16 | M13: 0 | N13: https://docs.google.com/spreadsheets/d/1rJWpHWvNTnTns40cjn2_dxmUvpqyLTv72yNpqNf-bDY
... A184: 大漢酵素生物科技股份有限公司 | B184: 轉單合約 | C184: 白乙君 | D184: 2406 | E184: 0 | F184: 0 | G184: 0 | H184: 0 | I184: 0 | J184: 0 | K184: 0 | L184: 0 | M184: 0 | N184: https://docs.google.com/spreadsheets/d/1sghctKJvxLcbt1Tlg8Wgv8uca0_iWdfAF53S82xGsn4

Sheet 2023-12
A1: 廠商名稱 | B1: 合作模式 | C1: 負責人 | D1: 銷售總額 | E1: 抽成 | F1: 平台維護費 | G1: 金流處理費 | H1: 行銷推廣費 | I1: 活動贊助費 | J1: 運費攤提 | K1: 人工處理費 | L1: 倉租加總 | M1: 吸收額 | N1: 報表連結
A2: 明奇食品有限公司 | B2: 寄倉新約 | C2: duncan.lin | D2: 21470 | E2: 4294 | F2: 115 | G2: 440 | H2: 748 | I2: 748 | J2: 1286 | K2: 628 | L2: 214 | M2: 0 | N2: https://docs.google.com/spreadsheets/d/1vYK8q5PRs3G4vynD54T2OXMh-HOVOFf7K504jMGZoag
A3: 萬灃興貿易有限公司 | B3: 寄倉新約 | C3: duncan.lin | D3: 32736 | E3: 6547 | F3: 166 | G3: 663 | H3: 1147 | I3: 1150 | J3: 1640 | K3: 188 | L3: 152 | M3: 0 | N3: https://docs.google.com/spreadsheets/d/1BUvhYfqfgW_bgb4gXFD0YfQrcJrE-9XZ5IN_r7VtmV0
A4: 愛上大數據股份有限公司 | B4: 轉單合約 | C4: duncan.lin | D4: 2370 | E4: 474 | F4: 0 | G4: 47 | H4: 190 | I4: 0 | J4: 0 | K4: 0 | L4: 0 | M4: 0 | N4: https://docs.google.com/spreadsheets/d/11hqei8bjcI-6ktXDhRZy395i-_5G6bAT04lgMWUM6XI
A5: 大誠益國際實業有限公司 | B5: 寄倉新約 | C5: nic.lin | D5: 71681 | E5: 14336 | F5: 363 | G5: 1434 | H5: 2511 | I5: 2511 | J5: 2456 | K5: 645 | L5: 58 | M5: 0 | N5: https://docs.google.com/spreadsheets/d/1GccH532vM6qaBo169CO3N7G_LY7jdYs-nx0EVjcR5HQ
A6: 登薾國際貿易股份有限公司 | B6: 寄倉新約 | C6: vivi.huang | D6: 7785 | E6: 1557 | F6: 39 | G6: 156 | H6: 271 | I6: 271 | J6: 425 | K6: 17 | L6: 39 | M6: 0 | N6: https://docs.google.com/spreadsheets/d/1J_8P7IfcFw_2wijNAQsPPTl8Kgbtg7Vlzk2Qrf_A5sQ
